Workbook

Sheet AD
B2: Tabla 1: | C2: Ïndece de actividad docente parcial y final durante un período de 4 años | X2: Tabla 2: | Y2: Umbral básico fijado
X3: según la categoría y dedicación del docente
B4: Período | C4: Categoría | D4: Dedicación | E4: Licencias | G4: Corrección temporal | I4: Actividad Docente | T4: Umbral | U4: Índice de Actividad | V4: Índice de Actividad | X4: Categoría | Y4: Dedicación | Z4: Umbral Básico
E5: c/goce sueldo | F5: s/goce sueldo | G5: Tiempo | H5: factor de | S5: Puntaje | T5: Básico | U5: Docente | V5: Docente | X5: (j) | Y5: (l) | Z5: UBDjl
B6: k | E6: (meses) | F6: (meses) | G6: (años) | H6: corrección | I6: Dimensiones | Q6: ADp | R6: ADp | U6: Parcial | V6: en k años | X6: T | Y6: EX | Z6: =Puntaje!W4 -> 31
B7: (años) | C7: (j) | D7: (l) | E7: (lcg) | F7: (lsg) | G7: (tp) | H7: fck | I7: AD1 | J7: AD2 | K7: AD3 | L7: AD4 | M7: AD5 | N7: AD6 | O7: AD7 | P7: AD8 | Q7: Total | R7: Medio | S7: PDpjl | T7: UBDpjl | U7: IA1pjl | V7: IA1kjl | X7: AS | Y7: EX | Z7: =Puntaje!W5 -> 31
B8: 1 | C8: AJ | D8: SE | E8: 5 | F8: 3 | G8: =1-(E8+F8)/12 -> 0.33333333 | H8: =B8/G8 -> 3 | I8: ='AD1'!G14 -> 1 | J8: ='AD2'!P9 -> 1 | K8: ='AD3'!I15 -> 3 | L8: ='AD4'!H9 -> 3 | M8: ='AD5'!J13 -> 3 | N8: ='AD6'!F9 -> 3 | O8: ='AD7'!E10 -> 3 | P8: ='AD8'!I10 -> 3 | Q8: =SUM(I8:P8) -> 20 | R8: =Q8/8 -> 2.5 | S8: =Puntaje!K4 -> 147.64815 | T8: =IF(AND(C8="T",D8="EX"),$Z$6,IF(AND(C8="AS",D8="EX"),$Z$7,IF(AND(C8="AJ",D8="EX"),$Z$8,IF(AND(C8="JTP",D8="EX"),$Z$9,IF(AND(C8="AY1",D8="EX"),$Z$10,IF(AND(C8="T",D8="SE"),$Z$11,IF(AND(C8="AS",D8="SE"),$Z$12,IF(AND(C8="AJ",D8="SE"),$Z$13,IF(AND(C8="JTP",D8="SE"),$Z$14,IF(AND(C8="AY1",D8="SE"),$Z$15,IF(AND(C8="T",D8="DS"),$Z$16,IF(AND(C8="AS",D8="DS"),$Z$17,IF(AND(C8="AJ",D8="DS"),$Z$18,IF(AND(C8="JTP",D8="DS"),$Z$19,IF(AND(C8="AY1",D8="DS"),$Z$20,IF(AND(C8="AY2",D8="DS"),$Z$21,0)))))))))))))))) -> 31 | U8: =S8/T8/G8 -> 14.28853 | V8: =S8/T8*H8 -> 14.28853 | X8: AJ | Y8: EX | Z8: =Puntaje!W6 -> 31
B9: 2 | C9: T | D9: SE | E9: 3 | F9: 0 | G9: =1-(E9+F9)/12 -> 0.75 | H9: =B9/SUM(G8:G9) -> 1.8461538 | I9: ='AD1'!J14 -> 1 | J9: ='AD2'!P17 -> 1 | K9: ='AD3'!I28 -> 3 | L9: ='AD4'!H18 -> 1 | M9: ='AD5'!J24 -> 1 | N9: ='AD6'!F17 -> 3 | O9: ='AD7'!E20 -> 3 | P9: ='AD8'!I21 -> 3 | Q9: =SUM(I9:P9) -> 16 | R9: =Q9/8 -> 2 | S9: =Puntaje!K5 -> 93.348148 | T9: =IF(AND(C9="T",D9="EX"),$Z$6,IF(AND(C9="AS",D9="EX"),$Z$7,IF(AND(C9="AJ",D9="EX"),$Z$8,IF(AND(C9="JTP",D9="EX"),$Z$9,IF(AND(C9="AY1",D9="EX"),$Z$10,IF(AND(C9="T",D9="SE"),$Z$11,IF(AND(C9="AS",D9="SE"),$Z$12,IF(AND(C9="AJ",D9="SE"),$Z$13,IF(AND(C9="JTP",D9="SE"),$Z$14,IF(AND(C9="AY1",D9="SE"),$Z$15,IF(AND(C9="T",D9="DS"),$Z$16,IF(AND(C9="AS",D9="DS"),$Z$17,IF(AND(C9="AJ",D9="DS"),$Z$18,IF(AND(C9="JTP",D9="DS"),$Z$19,IF(AND(C9="AY1",D9="DS"),$Z$20,IF(AND(C9="AY2",D9="DS"),$Z$21,0)))))))))))))))) -> 31 | U9: =S9/T9/G9 -> 4.0149741 | V9: =SUM(S8:S9)/SUM(T8:T9)*H9 -> 7.1760684 | X9: JTP | Y9: EX | Z9: =Puntaje!W7 -> 28
B10: 3 | C10: T | D10: EX | E10: 0 | F10: 0 | G10: =1-(E10+F10)/12 -> 1 | H10: =B10/SUM(G8:G10) -> 1.44 | I10: ='AD1'!M14 -> 3 | J10: ='AD2'!P25 -> 1 | K10: ='AD3'!I42 -> 3 | L10: ='AD4'!H28 -> 3 | M10: ='AD5'!J35 -> 0 | N10: ='AD6'!F26 -> 1 | O10: ='AD7'!E29 -> 1 | P10: ='AD8'!I32 -> 0 | Q10: =SUM(I10:P10) -> 12 | R10: =Q10/8 -> 1.5 | S10: =Puntaje!K6 -> 52.448148 | T10: =IF(AND(C10="T",D10="EX"),$Z$6,IF(AND(C10="AS",D10="EX"),$Z$7,IF(AND(C10="AJ",D10="EX"),$Z$8,IF(AND(C10="JTP",D10="EX"),$Z$9,IF(AND(C10="AY1",D10="EX"),$Z$10,IF(AND(C10="T",D10="SE"),$Z$11,IF(AND(C10="AS",D10="SE"),$Z$12,IF(AND(C10="AJ",D10="SE"),$Z$13,IF(AND(C10="JTP",D10="SE"),$Z$14,IF(AND(C10="AY1",D10="SE"),$Z$15,IF(AND(C10="T",D10="DS"),$Z$16,IF(AND(C10="AS",D10="DS"),$Z$17,IF(AND(C10="AJ",D10="DS"),$Z$18,IF(AND(C10="JTP",D10="DS"),$Z$19,IF(AND(C10="AY1",D10="DS"),$Z$20,IF(AND(C10="AY2",D10="DS"),$Z$21,0)))))))))))))))) -> 31 | U10: =S10/T10/G10 -> 1.6918757 | V10: =SUM(S8:S10)/SUM(T8:T10)*H10 -> 4.5436559 | X10: AY1 | Y10: EX | Z10: =Puntaje!W8 -> 26
B11: 4 | C11: T | D11: EX | E11: 0 | F11: 0 | G11: =1-(E11+F11)/12 -> 1 | H11: =B11/SUM(G8:G11) -> 1.2972973 | I11: ='AD1'!P14 -> 3 | J11: ='AD2'!P33 -> 1 | K11: ='AD3'!I55 -> 3 | L11: ='AD4'!H37 -> 3 | M11: ='AD5'!J46 -> 3 | N11: ='AD6'!F34 -> 0 | O11: ='AD7'!E38 -> 0 | P11: ='AD8'!I42 -> 0 | Q11: =SUM(I11:P11) -> 13 | R11: =Q11/8 -> 1.625 | S11: =Puntaje!K7 -> 70.531481 | T11: =IF(AND(C11="T",D11="EX"),$Z$6,IF(AND(C11="AS",D11="EX"),$Z$7,IF(AND(C11="AJ",D11="EX"),$Z$8,IF(AND(C11="JTP",D11="EX"),$Z$9,IF(AND(C11="AY1",D11="EX"),$Z$10,IF(AND(C11="T",D11="SE"),$Z$11,IF(AND(C11="AS",D11="SE"),$Z$12,IF(AND(C11="AJ",D11="SE"),$Z$13,IF(AND(C11="JTP",D11="SE"),$Z$14,IF(AND(C11="AY1",D11="SE"),$Z$15,IF(AND(C11="T",D11="DS"),$Z$16,IF(AND(C11="AS",D11="DS"),$Z$17,IF(AND(C11="AJ",D11="DS"),$Z$18,IF(AND(C11="JTP",D11="DS"),$Z$19,IF(AND(C11="AY1",D11="DS"),$Z$20,IF(AND(C11="AY2",D11="DS"),$Z$21,0)))))))))))))))) -> 31 | U11: =S11/T11/G11 -> 2.2752091 | V11: =SUM(S8:S11)/SUM(T8:T11)*H11 -> 3.8079434 | X11: T | Y11: SE | Z11: =Puntaje!W9 -> 31
G12: =SUM(G8:G11) -> 3.0833333 | I12: =SUM(I8:I11)/4 -> 2 | J12: =SUM(J8:J11)/4 -> 1 | K12: =SUM(K8:K11)/4 -> 3 | L12: =SUM(L8:L11)/4 -> 2.5 | M12: =SUM(M8:M11)/4 -> 1.75 | N12: =SUM(N8:N11)/4 -> 1.75 | O12: =SUM(O8:O11)/4 -> 1.75 | P12: =SUM(P8:P11)/4 -> 1.5 | Q12: =SUM(I12:P12) -> 15.25 | R12: =Q12/8 -> 1.90625 | S12: =SUM(S8:S11) -> 363.97593 | T12: =SUM(T8:T11) -> 124 | U12: =S12/T12*H11 -> 3.8079434 | X12: AS | Y12: SE | Z12: =Puntaje!W10 -> 31
X13: AJ | Y13: SE | Z13: =Puntaje!W11 -> 31
X14: JTP | Y14: SE | Z14: =Puntaje!W12 -> 28
X15: AY1 | Y15: SE | Z15: =Puntaje!W13 -> 26
X16: T | Y16: DS | Z16: =Puntaje!W14 -> 31
X17: AS | Y17: DS | Z17: =Puntaje!W15 -> 31
X18: AJ | Y18: DS | Z18: =Puntaje!W16 -> 31
X19: JTP | Y19: DS | Z19: =Puntaje!W17 -> 28
X20: AY1 | Y20: DS | Z20: =Puntaje!W18 -> 26
X21: AY2 | Y21: DS | Z21: =Puntaje!W19 -> 25

Sheet AD1
B2: Tabla 3: | C2: Puntajes y categorías alcanzados por el docente en los p años informados para la actividad docente AD1
E3: Período
E4: 1 | H4: 2 | K4: 3 | N4: 4 | S4: Cuadro 2.4.1.1: Puntaje (w) según formación académica | V4: Cuadro 2.4.1.2: Mínimos y superiores de PD1 según categoría docente
B5: AD1 - Formación Académica en el Año | E5: fai1 | F5: ci1 | G5: (fa.c.wfa)i1 | H5: fai2 | I5: ci2 | J5: (fa.c.wfa)i2 | K5: fai3 | L5: ci3 | M5: (fa.c.wfa)i3 | N5: fai4 | O5: ci4 | P5: (fa.c.wfa)i4 | S5: Formación Académica | T5: wfa | V5: Categoría | W5: Minimo | X5: Superior
C6: Pregrado | E6: 0 | F6: 0 | G6: =E6*F6*T6 -> 0 | H6: 0 | I6: 0 | J6: =H6*I6*T6 -> 0 | K6: 0 | L6: 0 | M6: =K6*L6*T6 -> 0 | N6: 0 | O6: 0 | P6: =N6*O6*T6 -> 0 | S6: Pregrado | T6: 1 | V6: Titular (T) | W6: 6 | X6: 8
C7: Grado | E7: 1 | F7: 1 | G7: =E7*F7*T7 -> 3 | H7: 1 | I7: 1 | J7: =H7*I7*T7 -> 3 | K7: 1 | L7: 1 | M7: =K7*L7*T7 -> 3 | N7: 1 | O7: 1 | P7: =N7*O7*T7 -> 3 | S7: Grado | T7: 3 | V7: Asociado (AS) | W7: 6 | X7: 8
C8: Posdoctorado | E8: 0 | F8: 0 | G8: =E8*F8*T8 -> 0 | H8: 0 | I8: 0 | J8: =H8*I8*T8 -> 0 | K8: 0 | L8: 0 | M8: =K8*L8*T8 -> 0 | N8: 0 | O8: 0 | P8: =N8*O8*T8 -> 0 | S8: Posdoctorado | T8: 6 | V8: Adjunto (AJ) | W8: 6 | X8: 8
C9: Doctorado | E9: 0 | F9: 0 | G9: =E9*F9*T9 -> 0 | H9: 0 | I9: 0 | J9: =H9*I9*T9 -> 0 | K9: 0 | L9: 0 | M9: =K9*L9*T9 -> 0 | N9: 1 | O9: 1 | P9: =N9*O9*T9 -> 5 | S9: Doctorado | T9: 5 | V9: Jefe de Trabajos Prácticos (JTP) | W9: 3 | X9: 5
B10: Tipos de Formación | C10: Maestría | E10: 1 | F10: 1 | G10: =E10*F10*T10 -> 3 | H10: 1 | I10: 1 | J10: =H10*I10*T10 -> 3 | K10: 1 | L10: 2 | M10: =K10*L10*T10 -> 6 | N10: 1 | O10: 2 | P10: =N10*O10*T10 -> 6 | S10: Maestría | T10: 3 | V10: Ayudante de Primera (AY1) | W10: 1 | X10: 3
B11: i | C11: Especialización | E11: 0 | F11: 0 | G11: =E11*F11*T11 -> 0 | H11: 0 | I11: 0 | J11: =H11*I11*T11 -> 0 | K11: 0 | L11: 0 | M11: =K11*L11*T11 -> 0 | N11: 0 | O11: 0 | P11: =N11*O11*T11 -> 0 | S11: Especialización | T11: 1 | V11: Ayudante de Segunda (AY2) | W11: 0 | X11: 2
C12: Diplomado | E12: 0 | F12: 0 | G12: =E12*F12*T12 -> 0 | H12: 1 | I12: 1 | J12: =H12*I12*T12 -> 0.5 | K12: 1 | L12: 1 | M12: =K12*L12*T12 -> 0.5 | N12: 1 | O12: 1 | P12: =N12*O12*T12 -> 0.5 | S12: Diplomado | T12: 0.5
F13: PD11 | G13: =SUM(G6:G12) -> 6 | I13: PD12 | J13: =SUM(J6:J12) -> 6.5 | L13: PD13 | M13: =SUM(M6:M12) -> 9.5 | O13: PD14 | P13: =SUM(P6:P12) -> 14.5
F14: AD11 | G14: =IF(AND(AD!C8="T",G13<$W$6),0,IF(AND(AD!C8="T",G13>$X$6),3,IF(AND(AD!C8="AS",G13<$W$7),0,IF(AND(AD!C8="AS",G13>$X$7),3,IF(AND(AD!C8="AJ",G13<$W$8),0,IF(AND(AD!C8="AJ",G13>$X$8),3,IF(AND(AD!C8="JTP",G13<$W$9),0,IF(AND(AD!C8="JTP",G13>$X$9),3,IF(AND(AD!C8="AY1",G13<$W$10),0,IF(AND(AD!C8="AY1",G13>$X$10),3,IF(AND(AD!C8="AY2",G13=0),0,IF(AND(AD!C8="AY2",G13>1),3,IF(AND(AD!C8="AY2",G13<1),0,1))))))))))))) -> 1 | I14: AD12 | J14: =IF(AND(AD!C9="T",J13<$W$6),0,IF(AND(AD!C9="T",J13>$X$6),3,IF(AND(AD!C9="AS",J13<$W$7),0,IF(AND(AD!C9="AS",J13>$X$7),3,IF(AND(AD!C9="AJ",J13<$W$8),0,IF(AND(AD!C9="AJ",J13>$X$8),3,IF(AND(AD!C9="JTP",J13<$W$9),0,IF(AND(AD!C98="JTP",J13>$X$9),3,IF(AND(AD!C9="AY1",J13<$W$10),0,IF(AND(AD!C9="AY1",J13>$X$10),3,IF(AND(AD!C98="AY2",J13=0),0,IF(AND(AD!C9="AY2",J13>1),3,IF(AND(AD!C9="AY2",J13<1),0,1))))))))))))) -> 1 | L14: AD13 | M14: =IF(AND(AD!C10="T",M13<$W$6),0,IF(AND(AD!C10="T",M13>$X$6),3,IF(AND(AD!C10="AS",M13<$W$7),0,IF(AND(AD!C10="AS",M13>$X$7),3,IF(AND(AD!C10="AJ",M13<$W$8),0,IF(AND(AD!C10="AJ",M13>$X$8),3,IF(AND(AD!C10="JTP",M13<$W$9),0,IF(AND(AD!C10="JTP",M13>$X$9),3,IF(AND(AD!C10="AY1",M13<$W$10),0,IF(AND(AD!C10="AY1",M13>$X$10),3,IF(AND(AD!C10="AY2",M13=0),0,IF(AND(AD!C10="AY2",M13>1),3,IF(AND(AD!C10="AY2",M13<1),0,1))))))))))))) -> 3 | O14: AD14 | P14: =IF(AND(AD!C11="T",P13<$W$6),0,IF(AND(AD!C11="T",P13>$X$6),3,IF(AND(AD!C11="AS",P13<$W$7),0,IF(AND(AD!C11="AS",P13>$X$7),3,IF(AND(AD!C11="AJ",P13<$W$8),0,IF(AND(AD!C11="AJ",P13>$X$8),3,IF(AND(AD!C11="JTP",P13<$W$9),0,IF(AND(AD!C11="JTP",P13>$X$9),3,IF(AND(AD!C11="AY1",P13<$W$10),0,IF(AND(AD!C11="AY1",P13>$X$10),3,IF(AND(AD!C11="AY2",P13=0),0,IF(AND(AD!C11="AY2",P13>1),3,IF(AND(AD!C11="AY2",P13<1),0,1))))))))))))) -> 3
S15: Cuadro 2.4.1.3: Valorización de AD1 según valor de PD1
B16: fai1: Formación Académica i en el primer año | S16: En relación al PD1 | T16: AD1
B17: (f.a.w)i1: Puntaje en formación académica i en el primer año | S17: Menor al mínimo | T17: 0
S18: Alcanza el mínimo | T18: 1
S19: Supera un valor límite | T19: 3

Sheet AD2
B1: Tabla 4: | C1: Puntajes y categorías alcanzados por el docente en los p años informados para la actividad docente AD2
B3: AD2 - Actualización y capacitación en docencia | R3: Cuadro 2.4.2.1: Horas- créditos según actividad de la dimensión
B4: Año | C4: Nombre del curso | D4: Institución | E4: Lugar | F4: Fecha | G4: Cursos | H4: Taller | I4: Asistencia | J4: Aprobado | K4: Form Oblig | L4: Horas | M4: acwi1 | N4: Pasantía | O4: Distinción | P4: aci1 | R4: Actualización y Capacitación | T4: wcp
B5: 1 | C5: Variable Aleatoria | D5: GAB | E5: Tucumán | F5: 44481 | G5: 1 | H5: 0 | I5: 1 | J5: 1 | K5: 0 | L5: 30 | M5: =IF(AND(G5=1,J5=1),L5/$T$5,IF(AND(G5=1,I5=1),L5/$T$6,IF(AND(H5=1,J5=1),L5/$T$7,IF(AND(H5=1,I5=1),L5/$T$8,IF(AND(K5=1,J5=1), L5/$T$9,0))))) -> 1.2 | N5: 0 | O5: 0 | P5: =M5+IF(N5=1,$T$14,0)+IF(O5=1,$T$15,0) -> 1.2 | R5: Cursos | S5: Asistencia y Aprobado | T5: 25
B6: 1 | C6: Distribuciones | D6: GAB | E6: Tucumán | F6: 44482 | G6: 1 | H6: 0 | I6: 1 | J6: 1 | K6: 0 | L6: 25 | M6: =IF(AND(G6=1,J6=1),L6/$T$5,IF(AND(G6=1,I6=1),L6/$T$6,IF(AND(H6=1,J6=1),L6/$T$7,IF(AND(H6=1,I6=1),L6/$T$8,IF(AND(K6=1,J6=1), L6/$T$9,0))))) -> 1 | N6: 0 | O6: 0 | P6: =M6+IF(N6=1,$T$14,0)+IF(O6=1,$T$15,0) -> 1 | S6: Asistencia | T6: 50
B7: 1 | C7: Binomial | D7: GAB | E7: Tucumán | F7: 44482 | G7: 1 | H7: 0 | I7: 1 | J7: 0 | K7: 0 | L7: 30 | M7: =IF(AND(G7=1,J7=1),L7/$T$5,IF(AND(G7=1,I7=1),L7/$T$6,IF(AND(H7=1,J7=1),L7/$T$7,IF(AND(H7=1,I7=1),L7/$T$8,IF(AND(K7=1,J7=1), L7/$T$9,0))))) -> 0.6 | N7: 0 | O7: 0 | P7: =M7+IF(N7=1,$T$14,0)+IF(O7=1,$T$15,0) -> 0.6 | R7: Talleres | S7: Asistencia y Aprobado | T7: 25
O8: PD21 | P8: =SUM(P5:P7) -> 2.8 | S8: Asistencia | T8: 50
O9: AD21 | P9: =IF(P8>5, 3,IF(P8>0,1,0)) -> 1 | R9: Formaciones Obligatorias (ODS, ley Micaela, etc) | S9: Aprobado | T9: 25
B11: AD2 - Actualización y capacitación en docencia
B12: Año | C12: Nombre del curso | D12: Institución | E12: Lugar | F12: Fecha | G12: Cursos | H12: Taller | I12: Asistencia | J12: Aprobado | K12: Form Oblig | L12: Horas | M12: acwi2 | N12: Pasantía | O12: Distinción | P12: aci2 | R12: Cuadro 2.4.2.2: Créditos según actividad de la dimensión
B13: 2 | C13: Análiisis de dato | D13: FCA | E13: Mendoza | F13: 44656 | G13: 0 | H13: 1 | I13: 0 | J13: 1 | K13: 0 | L13: 30 | M13: =IF(AND(G13=1,J13=1),L13/$T$5,IF(AND(G13=1,I13=1),L13/$T$6,IF(AND(H13=1,J13=1),L13/$T$7,IF(AND(H13=1,I13=1),L13/$T$8,IF(AND(K13=1,J13=1), L13/$T$9,0))))) -> 1.2 | N13: 0 | O13: 0 | P13: =M13+IF(N13=1,$T$14,0)+IF(O13=1,$T$15,0) -> 1.2 | R13: Capatación y distinción | T13: Créditos
B14: 2 | C14: PP | D14: FCA | E14: Salta | F14: 44676 | G14: 0 | H14: 1 | I14: 1 | J14: 0 | K14: 0 | L14: 25 | M14: =IF(AND(G14=1,J14=1),L14/$T$5,IF(AND(G14=1,I14=1),L14/$T$6,IF(AND(H14=1,J14=1),L14/$T$7,IF(AND(H14=1,I14=1),L14/$T$8,IF(AND(K14=1,J14=1), L14/$T$9,0))))) -> 0.5 | N14: 0 | O14: 0 | P14: =M14+IF(N14=1,$T$14,0)+IF(O14=1,$T$15,0) -> 0.5 | R14: Pasantías | T14: 5
B15: 2 | C15: Premio docente | D15: Embajada | E15: Mendoza | F15: 44668 | G15: 0 | H15: 0 | I15: 0 | J15: 0 | K15: 0 | L15: 0 | M15: =IF(AND(G15=1,J15=1),L15/$T$5,IF(AND(G15=1,I15=1),L15/$T$6,IF(AND(H15=1,J15=1),L15/$T$7,IF(AND(H15=1,I15=1),L15/$T$8,IF(AND(K15=1,J15=1), L15/$T$9,0))))) -> 0 | N15: 0 | O15: 0 | P15: =M15+IF(N15=1,$T$14,0)+IF(O15=1,$T$15,0) -> 0 | R15: Distinción | T15: 0.5
O16: PD22 | P16: =SUM(P13:P15) -> 1.7
O17: AD22 | P17: =IF(P16>5, 3,IF(P16>0,1,0)) -> 1
R18: Cuadro 2.4.2.3: Caracterización de AD2
B19: AD2 - Actualización y capacitación en docencia | R19: PD2 | S19: Categoría AD2
B20: Año | C20: Nombre del curso | D20: Institución | E20: Lugar | F20: Fecha | G20: Cursos | H20: Taller | I20: Asistencia | J20: Aprobado | K20: Form Oblig | L20: Horas | M20: acwi3 | N20: Pasantía | O20: Distinción | P20: aci3 | R20: 0 | S20: 0
B21: 3 | C21: Juju | D21: FCA | E21: Mendoza | F21: 44988 | G21: 0 | H21: 1 | I21: 0 | J21: 1 | K21: 0 | L21: 30 | M21: =IF(AND(G21=1,J21=1),L21/$T$5,IF(AND(G21=1,I21=1),L21/$T$6,IF(AND(H21=1,J21=1),L21/$T$7,IF(AND(H21=1,I21=1),L21/$T$8,IF(AND(K21=1,J21=1), L21/$T$9,0))))) -> 1.2 | N21: 0 | O21: 0 | P21: =M21+IF(N21=1,$T$14,0)+IF(O21=1,$T$15,0) -> 1.2 | R21: 1 - 5 | S21: 1
B22: 3 | C22: Ley Micaela | D22: UNCUYO | F22: 45051 | G22: 0 | H22: 0 | I22: 0 | J22: 1 | K22: 1 | L22: 30 | M22: =IF(AND(G22=1,J22=1),L22/$T$5,IF(AND(G22=1,I22=1),L22/$T$6,IF(AND(H22=1,J22=1),L22/$T$7,IF(AND(H22=1,I22=1),L22/$T$8,IF(AND(K22=1,J22=1), L22/$T$9,0))))) -> 1.2 | N22: 0 | O22: 0 | P22: =M22+IF(N22=1,$T$14,0)+IF(O22=1,$T$15,0) -> 1.2 | R22: >5 | S22: 3
B23: 3 | G23: 0 | H23: 0 | I23: 0 | J23: 0 | K23: 0 | L23: 0 | M23: =IF(AND(G23=1,J23=1),L23/$T$5,IF(AND(G23=1,I23=1),L23/$T$6,IF(AND(H23=1,J23=1),L23/$T$7,IF(AND(H23=1,I23=1),L23/$T$8,IF(AND(K23=1,J23=1), L23/$T$9,0))))) -> 0 | N23: 0 | O23: 0 | P23: =M23+IF(N23=1,$T$14,0)+IF(O23=1,$T$15,0) -> 0
O24: PD23 | P24: =SUM(P21:P23) -> 2.4
O25: AD23 | P25: =IF(P24>5, 3,IF(P24>0,1,0)) -> 1
B27: AD2 - Actualización y capacitación en docencia
B28: Año | C28: Nombre del curso | D28: Institución | E28: Lugar | F28: Fecha | G28: Cursos | H28: Taller | I28: Asistencia | J28: Aprobado | K28: Form Oblig | L28: Horas | M28: acwi4 | N28: Pasantía | O28: Distinción | P28: aci4
B29: 4 | C29: NN | D29: FCE | E29: Mendoza | F29: 45416 | G29: 1 | H29: 0 | I29: 1 | J29: 1 | K29: 0 | L29: 40 | M29: =IF(AND(G29=1,J29=1),L29/$T$5,IF(AND(G29=1,I29=1),L29/$T$6,IF(AND(H29=1,J29=1),L29/$T$7,IF(AND(H29=1,I29=1),L29/$T$8,IF(AND(K29=1,J29=1), L29/$T$9,0))))) -> 1.6 | N29: 0 | O29: 0 | P29: =M29+IF(N29=1,$T$14,0)+IF(O29=1,$T$15,0) -> 1.6
B30: 4 | C30: ll | D30: Instituto | E30: Mendoza | F30: 45448 | G30: 0 | H30: 1 | I30: 1 | J30: 1 | K30: 0 | L30: 20 | M30: =IF(AND(G30=1,J30=1),L30/$T$5,IF(AND(G30=1,I30=1),L30/$T$6,IF(AND(H30=1,J30=1),L30/$T$7,IF(AND(H30=1,I30=1),L30/$T$8,IF(AND(K30=1,J30=1), L30/$T$9,0))))) -> 0.8 | N30: 0 | O30: 0 | P30: =M30+IF(N30=1,$T$14,0)+IF(O30=1,$T$15,0) -> 0.8
B31: 4 | G31: 0 | H31: 0 | I31: 0 | J31: 0 | K31: 0 | L31: 0 | M31: =IF(AND(G31=1,J31=1),L31/$T$5,IF(AND(G31=1,I31=1),L31/$T$6,IF(AND(H31=1,J31=1),L31/$T$7,IF(AND(H31=1,I31=1),L31/$T$8,IF(AND(K31=1,J31=1), L31/$T$9,0))))) -> 0 | N31: 0 | O31: 0 | P31: =M31+IF(N31=1,$T$14,0)+IF(O31=1,$T$15,0) -> 0
O32: PD24 | P32: =SUM(P29:P31) -> 2.4
O33: AD24 | P33: =IF(P32>5, 3,IF(P32>0,1,0)) -> 1

Sheet AD3
B2: AD3- Docencia en las carreras de pregrado y grado de la unidad académica en el Año | L2: Cuadro 2.4.3.1: Ponderación de los espacios curriculares (Ec) según complejidad
B3: Año | C3: Carrera | D3: Espacio Curricular | E3: Tipos de Espacio | F3: Dotación Acorde | G3: Carga | H3: Estudiantes | I3: Docencia | L3: Tipo de Ec | M3: Complejidad | N3: Dotación Acorde (Dac)
E4: Curricular | F4: Tec | G4: Horaria | H4: Inscriptos | I4: pre y grado | L4: 1 | M4: Asignaturas teóricas | N4: 2
B5: (p) | D5: (Ec) | E5: (Tec) | F5: (Dac) | G5: (Ch) | H5: (Cei) | I5: dgip | L5: 2 | M5: Asignaturas teóricas-aplicadas | N5: 3
B6: 1 | C6: IA | D6: Estadística y Diseño Experimental | E6: 2 | F6: =IF(E6=1,$N$4,IF(E6=2,$N$5,IF(E6=3,$N$6,IF(E6=4,$N$7,0)))) -> 3 | G6: 95 | H6: 190 | I6: =G6/$M$13*H6/$M$14*F6 -> 6.6851852 | L6: 3 | M6: Talleres y Laboratorios | N6: 5
B7: 1 | C7: LB | D7: Estadística Aplicada | E7: 2 | F7: =IF(E7=1,$N$4,IF(E7=2,$N$5,IF(E7=3,$N$6,IF(E7=4,$N$7,0)))) -> 3 | G7: 90 | H7: 48 | I7: =G7/$M$13*H7/$M$14*F7 -> 1.6 | L7: 4 | M7: Prácticas de campo supervisadas | N7: 12
B8: 1 | C8: IRN | D8: Bioestadística | E8: 2 | F8: =IF(E8=1,$N$4,IF(E8=2,$N$5,IF(E8=3,$N$6,IF(E8=4,$N$7,0)))) -> 3 | G8: 90 | H8: 73 | I8: =G8/$M$13*H8/$M$14*F8 -> 2.4333333 | M8: Seminarios
B9: 1 | C9: B | D9: Estadística Módulo I | E9: 2 | F9: =IF(E9=1,$N$4,IF(E9=2,$N$5,IF(E9=3,$N$6,IF(E9=4,$N$7,0)))) -> 3 | G9: 50 | H9: 1 | I9: =G9/$M$13*H9/$M$14*F9 -> 0.018518519 | M9: Seminarios tutoriados
B10: 1 | C10: B | D10: Herramientas Básicas de Informática | E10: 2 | F10: =IF(E10=1,$N$4,IF(E10=2,$N$5,IF(E10=3,$N$6,IF(E10=4,$N$7,0)))) -> 3 | G10: 30 | H10: 45 | I10: =G10/$M$13*H10/$M$14*F10 -> 0.5 | L10: Referencia: Mapa Docendi
B11: 1 | C11: IA | D11: Informática Aplicada | E11: 2 | F11: =IF(E11=1,$N$4,IF(E11=2,$N$5,IF(E11=3,$N$6,IF(E11=4,$N$7,0)))) -> 3 | G11: 50 | H11: 114 | I11: =G11/$M$13*H11/$M$14*F11 -> 2.1111111
B12: 1 | C12: IRN | D12: Aplicación de Programas Informáticos | E12: 2 | F12: =IF(E12=1,$N$4,IF(E12=2,$N$5,IF(E12=3,$N$6,IF(E12=4,$N$7,0)))) -> 3 | G12: 60 | H12: 18 | I12: =G12/$M$13*H12/$M$14*F12 -> 0.4 | L12: Estandarización según el Mapa Docendi
I13: =G13/$M$13*H13/$M$14*F13 -> 0 | L13: Che | M13: 90
H14: PD31 | I14: =SUM(I6:I13) -> 13.748148 | L14: Cee | M14: 90
H15: AD31 | I15: =IF(I14>5,3,IF(I14>1,1,0)) -> 3
L16: Cuadro 2.4.3.2: Caracterización de AD3
L17: PD3 | M17: Categoría AD3
B18: AD3- Docencia en las carreras de pregrado y grado de la unidad académica en el Año | L18: 0 | M18: 0
B19: Año | C19: Carrera | D19: Espacio Curricular | E19: Tipos de Espacio | F19: Dotación Acorde | G19: Carga | H19: Estudiantes | I19: Docencia | L19: 1 - 5 | M19: 1
E20: Curricular | F20: Tec | G20: Horaria | H20: Inscriptos | I20: pre y grado | L20: >5 | M20: 3
B21: (p) | D21: (Ec) | E21: (Tec) | F21: (Dac) | G21: (Ch) | H21: (Cei) | I21: dgip
B22: 2 | C22: IA | D22: Estadística y Diseño Experimental | E22: 2 | F22: =IF(E22=1,$N$4,IF(E22=2,$N$5,IF(E22=3,$N$6,IF(E22=4,$N$7,0)))) -> 3 | G22: 120 | H22: 180 | I22: =G22/$M$13*H22/$M$14*F22 -> 8
B23: 2 | C23: LB | D23: Estadística Aplicada | E23: 2 | F23: =IF(E23=1,$N$4,IF(E23=2,$N$5,IF(E23=3,$N$6,IF(E23=4,$N$7,0)))) -> 3 | G23: 100 | H23: 40 | I23: =G23/$M$13*H23/$M$14*F23 -> 1.4814815
B24: 2 | C24: IRN | D24: Bioestadística | E24: 2 | F24: =IF(E24=1,$N$4,IF(E24=2,$N$5,IF(E24=3,$N$6,IF(E24=4,$N$7,0)))) -> 3 | G24: 80 | H24: 120 | I24: =G24/$M$13*H24/$M$14*F24 -> 3.5555556
B25: 2 | D25: Prueba | E25: 2 | F25: =IF(E25=1,$N$4,IF(E25=2,$N$5,IF(E25=3,$N$6,IF(E25=4,$N$7,0)))) -> 3 | G25: 6 | H25: 5 | I25: =G25/$M$13*H25/$M$14*F25 -> 0.011111111
E26: 0 | F26: =IF(E26=1,$N$4,IF(E26=2,$N$5,IF(E26=3,$N$6,IF(E26=4,$N$7,0)))) -> 0 | G26: 0 | H26: 0 | I26: =G26/$M$13*H26/$M$14*F26 -> 0
H27: PD32 | I27: =SUM(I22:I26) -> 13.048148
H28: AD32 | I28: =IF(I27>5,3,IF(I27>1,1,0)) -> 3
B32: AD3- Docencia en las carreras de pregrado y grado de la unidad académica en el Año
B33: Año | C33: Carrera | D33: Espacio Curricular | E33: Tipos de Espacio | F33: Dotación Acorde | G33: Carga | H33: Estudiantes | I33: Docencia
E34: Curricular | F34: Tec | G34: Horaria | H34: Inscriptos | I34: pre y grado
B35: (p) | D35: (Ec) | E35: (Tec) | F35: (Dac) | G35: (Ch) | H35: (Cei) | I35: dgip
B36: 3 | C36: IA | D36: Estadística y Diseño Experimental | E36: 2 | F36: =IF(E36=1,$N$4,IF(E36=2,$N$5,IF(E36=3,$N$6,IF(E36=4,$N$7,0)))) -> 3 | G36: 120 | H36: 180 | I36: =G36/$M$13*H36/$M$14*F36 -> 8
B37: 3 | C37: LB | D37: Estadística Aplicada | E37: 2 | F37: =IF(E37=1,$N$4,IF(E37=2,$N$5,IF(E37=3,$N$6,IF(E37=4,$N$7,0)))) -> 3 | G37: 100 | H37: 40 | I37: =G37/$M$13*H37/$M$14*F37 -> 1.4814815
B38: 3 | C38: IRN | D38: Bioestadística | E38: 2 | F38: =IF(E38=1,$N$4,IF(E38=2,$N$5,IF(E38=3,$N$6,IF(E38=4,$N$7,0)))) -> 3 | G38: 80 | H38: 120 | I38: =G38/$M$13*H38/$M$14*F38 -> 3.5555556
B39: 3 | D39: Prueba | E39: 2 | F39: =IF(E39=1,$N$4,IF(E39=2,$N$5,IF(E39=3,$N$6,IF(E39=4,$N$7,0)))) -> 3 | G39: 6 | H39: 5 | I39: =G39/$M$13*H39/$M$14*F39 -> 0.011111111
F40: =IF(E40=1,$N$4,IF(E40=2,$N$5,IF(E40=3,$N$6,IF(E40=4,$N$7,0)))) -> 0 | H40: 0 | I40: =G40/$M$13*H40/$M$14*F40 -> 0
H41: PD33 | I41: =SUM(I36:I40) -> 13.048148
H42: AD33 | I42: =IF(I41>5,3,IF(I41>1,1,0)) -> 3
B45: AD3- Docencia en las carreras de pregrado y grado de la unidad académica en el Año
B46: Año | C46: Carrera | D46: Espacio Curricular | E46: Tipos de Espacio | F46: Dotación Acorde | G46: Carga | H46: Estudiantes | I46: Docencia
...

Sheet AD4
B2: AD4: Docencia de Posgrado y Otros | J2: Cuadro 2.4.4.1: Valoración según carrera | N2: Cuadro 2.4.4.2: Caracterización de AD4
B3: Año | C3: Carrera | D3: Asignatura | E3: Créditos | F3: Participación | G3: Valoración | H3: dpip | J3: 1 | K3: Carrera | L3: Puntaje | N3: PD4 | O3: Categoría AD4
B4: p | F4: (%) | J4: 1 | K4: Doctorado | L4: 7 | N4: 0 | O4: 0
B5: 1 | C5: 1 | D5: Estadística Aplicada | E5: 3 | F5: 30 | G5: =IF(C5=1,$L$4,IF(C5=2,$L$5,IF(C5=3,$L$6,IF(C5=4,$L$7, IF(C5=5,$L$8,0))))) -> 7 | H5: =E5*F5/100*G5 -> 6.3 | J5: 2 | K5: Maestría | L5: 5 | N5: 1 - 2 | O5: 1
B6: 1 | C6: 2 | D6: Estadística I | E6: 4 | F6: 20 | G6: =IF(C6=1,$L$4,IF(C6=2,$L$5,IF(C6=3,$L$6,IF(C6=4,$L$7, IF(C6=5,$L$8,0))))) -> 5 | H6: =E6*F6/100*G6 -> 4 | J6: 3 | K6: Especialización | L6: 3 | N6: >2 | O6: 3
B7: 1 | C7: 3 | D7: Estadística | E7: 3 | F7: 20 | G7: =IF(C7=1,$L$4,IF(C7=2,$L$5,IF(C7=3,$L$6,IF(C7=4,$L$7, IF(C7=5,$L$8,0))))) -> 3 | H7: =E7*F7/100*G7 -> 1.8 | J7: 4 | K7: Diplomatura | L7: 1
G8: PD41 | H8: =SUM(H5:H7) -> 12.1 | J8: 5 | K8: Diplomado | L8: 0.5
G9: AD41 | H9: =IF(H8>2,3,IF(H8=0,0,1)) -> 3
B12: Año | C12: Carrera | D12: Asignatura | E12: Créditos | F12: Participación | G12: Valoración | H12: dpip
B13: p | F13: (%)
B14: 2 | C14: 4 | D14: Nutrición | E14: 2 | F14: 30 | G14: =IF(C14=1,$L$4,IF(C14=2,$L$5,IF(C14=3,$L$6,IF(C14=4,$L$7, IF(C14=5,$L$8,0))))) -> 1 | H14: =E14*F14/100*G14 -> 0.6
B15: 2 | C15: 5 | D15: pp | E15: 1 | F15: 100 | G15: =IF(C15=1,$L$4,IF(C15=2,$L$5,IF(C15=3,$L$6,IF(C15=4,$L$7, IF(C15=5,$L$8,0))))) -> 0.5 | H15: =E15*F15/100*G15 -> 0.5
B16: 2 | C16: 0 | E16: 0 | F16: 0 | G16: =IF(C16=1,$L$4,IF(C16=2,$L$5,IF(C16=3,$L$6,IF(C16=4,$L$7, IF(C16=5,$L$8,0))))) -> 0 | H16: =E16*F16/100*G16 -> 0
G17: PD42 | H17: =SUM(H14:H16) -> 1.1
G18: AD42 | H18: =IF(H17>2,3,IF(H17=0,0,1)) -> 1
B22: Año | C22: Carrera | D22: Asignatura | E22: Créditos | F22: Participación | G22: Valoración | H22: dpip
B23: p | F23: (%)
B24: 3 | C24: 2 | D24: Estadística Aplicada | E24: 2 | F24: 30 | G24: =IF(C24=1,$L$4,IF(C24=2,$L$5,IF(C24=3,$L$6,IF(C24=4,$L$7, IF(C24=5,$L$8,0))))) -> 5 | H24: =E24*F24/100*G24 -> 3
B25: 3 | C25: 2 | D25: Estadística I | E25: 2 | F25: 5 | G25: =IF(C25=1,$L$4,IF(C25=2,$L$5,IF(C25=3,$L$6,IF(C25=4,$L$7, IF(C25=5,$L$8,0))))) -> 5 | H25: =E25*F25/100*G25 -> 0.5
B26: 3 | C26: 0 | E26: 0 | F26: 0 | G26: =IF(C26=1,$L$4,IF(C26=2,$L$5,IF(C26=3,$L$6,IF(C26=4,$L$7, IF(C26=5,$L$8,0))))) -> 0 | H26: =E26*F26/100*G26 -> 0
G27: PD43 | H27: =SUM(H24:H26) -> 3.5
G28: AD43 | H28: =IF(H27>2,3,IF(H27=0,0,1)) -> 3
B31: Año | C31: Carrera | D31: Asignatura | E31: Créditos | F31: Participación | G31: Valoración | H31: dpip
B32: p | F32: (%)
B33: 4 | C33: 2 | D33: Estadística Aplicada | E33: 2 | F33: 30 | G33: =IF(C33=1,$L$4,IF(C33=2,$L$5,IF(C33=3,$L$6,IF(C33=4,$L$7, IF(C33=5,$L$8,0))))) -> 5 | H33: =E33*F33/100*G33 -> 3
B34: 4 | C34: 2 | D34: Estadística I | E34: 2 | F34: 5 | G34: =IF(C34=1,$L$4,IF(C34=2,$L$5,IF(C34=3,$L$6,IF(C34=4,$L$7, IF(C34=5,$L$8,0))))) -> 5 | H34: =E34*F34/100*G34 -> 0.5
B35: 4 | C35: 0 | E35: 0 | F35: 0 | G35: =IF(C35=1,$L$4,IF(C35=2,$L$5,IF(C35=3,$L$6,IF(C35=4,$L$7, IF(C35=5,$L$8,0))))) -> 0 | H35: =E35*F35/100*G35 -> 0
G36: PD44 | H36: =SUM(H33:H35) -> 3.5
G37: AD44 | H37: =IF(H36>2,3,IF(H36=0,0,1)) -> 3

Sheet AD5
B3: AD5: Participación en reuniones científicas con referencia a la docencia | L3: Cuadro 2.4.5.1: Valoración según el tipo de participación | O3: Cuadro 2.4.5.2:Valoración según tipo de presentación
B4: Año | C4: Evento | D4: Participación | F4: Presentación | J4: dei1 | L4: Tipo de Participación | M4: Vpa | O4: Tipo | P4: Referato | Q4: Vpr
B5: p | D5: Tipo | E5: Vpai | F5: Tipo | G5: Título | H5: ´Referato | I5: Vpri | L5: Asistente | M5: 1 | O5: Resumen | P5: 0 | Q5: 1
B6: 1 | C6: Coloquio | D6: Asistente | E6: =IF(D6="Asistente",$M$5,IF(D6="Expositor",$M$6,IF(D6="Organización",$M$7,IF(D6="Evaluador",$M$8,0)))) -> 1 | F6: Resumen | G6: El Pronóstico | H6: 1 | I6: =IF(F6="Resumen",IF(H6=0,$Q$5,$Q$6),IF(F6="Trabajo Extendido",IF(H6=0,$Q$7,$Q$8),IF(F6="Trabajo Completo",IF(H6=0,$Q$9,$Q$10),0))) -> 3 | J6: =E6+I6 -> 4 | L6: Expositor | M6: 3 | P6: 1 | Q6: 3
B7: 1 | C7: UNCUYO | D7: Expositor | E7: =IF(D7="Asistente",$M$5,IF(D7="Expositor",$M$6,IF(D7="Organización",$M$7,IF(D7="Evaluador",$M$8,0)))) -> 3 | F7: Trabajo Extendido | G7: El Pronóstico | H7: 1 | I7: =IF(F7="Resumen",IF(H7=0,$Q$5,$Q$6),IF(F7="Trabajo Extendido",IF(H7=0,$Q$7,$Q$8),IF(F7="Trabajo Completo",IF(H7=0,$Q$9,$Q$10),0))) -> 5 | J7: =E7+I7 -> 8 | L7: Organización | M7: 4 | O7: Trabajo Extendido | P7: 0 | Q7: 3
B8: 1 | C8: FGDGG | D8: Expositor | E8: =IF(D8="Asistente",$M$5,IF(D8="Expositor",$M$6,IF(D8="Organización",$M$7,IF(D8="Evaluador",$M$8,0)))) -> 3 | F8: Trabajo Completo | G8: El Pronóstico | H8: 1 | I8: =IF(F8="Resumen",IF(H8=0,$Q$5,$Q$6),IF(F8="Trabajo Extendido",IF(H8=0,$Q$7,$Q$8),IF(F8="Trabajo Completo",IF(H8=0,$Q$9,$Q$10),0))) -> 8 | J8: =E8+I8 -> 11 | L8: Evaluador | M8: 5 | P8: 1 | Q8: 5
B9: 1 | C9: SSE | D9: Organización | E9: =IF(D9="Asistente",$M$5,IF(D9="Expositor",$M$6,IF(D9="Organización",$M$7,IF(D9="Evaluador",$M$8,0)))) -> 4 | I9: =IF(F9="Resumen",IF(H9=0,$Q$5,$Q$6),IF(F9="Trabajo Extendido",IF(H9=0,$Q$7,$Q$8),IF(F9="Trabajo Completo",IF(H9=0,$Q$9,$Q$10),0))) -> 0 | J9: =E9+I9 -> 4 | O9: Trabajo Completo | P9: 0 | Q9: 5
B10: 1 | C10: pppp | D10: Evaluador | E10: =IF(D10="Asistente",$M$5,IF(D10="Expositor",$M$6,IF(D10="Organización",$M$7,IF(D10="Evaluador",$M$8,0)))) -> 5 | I10: =IF(F10="Resumen",IF(H10=0,$Q$5,$Q$6),IF(F10="Trabajo Extendido",IF(H10=0,$Q$7,$Q$8),IF(F10="Trabajo Completo",IF(H10=0,$Q$9,$Q$10),0))) -> 0 | J10: =E10+I10 -> 5 | P10: 1 | Q10: 8
E11: =IF(D11="Asistente",$M$5,IF(D11="Expositor",$M$6,IF(D11="Organización",$M$7,IF(D11="Evaluador",$M$8,0)))) -> 0 | I11: =IF(F11="Resumen",IF(H11=0,$Q$5,$Q$6),IF(F11="Trabajo Extendido",IF(H11=0,$Q$7,$Q$8),IF(F11="Trabajo Completo",IF(H11=0,$Q$9,$Q$10),0))) -> 0 | J11: =E11+I11 -> 0 | O11: Referato: 0 es No y 1 es Sí
I12: PD51 | J12: =SUM(J6:J11) -> 32
I13: AD51 | J13: =IF(J12>5,3,IF(J12>1,1,0)) -> 3
O14: Cuadro 2.4.5.3: Caracterización de AD5
B15: Año | C15: Evento | D15: Participación | F15: Presentación | J15: dei2 | O15: PD5 | P15: Categoría AD5
B16: p | D16: Tipo | E16: Vpai | F16: Tipo | G16: Título | H16: ´Referato | I16: Valor | O16: 0 | P16: 0
B17: 2 | C17: Coloquio | D17: Asistente | E17: =IF(D17="Asistente",$M$5,IF(D17="Expositor",$M$6,IF(D17="Organización",$M$7,IF(D17="Evaluador",$M$8,0)))) -> 1 | F17: Resumen | G17: El Pronóstico | H17: 1 | I17: =IF(F17="Resumen",IF(H17=0,$Q$5,$Q$6),IF(F17="Trabajo Extendido",IF(H17=0,$Q$7,$Q$8),IF(F17="Trabajo Completo",IF(H17=0,$Q$9,$Q$10),0))) -> 3 | J17: =E17+I17 -> 4 | O17: 1 - 5 | P17: 1
B18: 2 | E18: =IF(D18="Asistente",$M$5,IF(D18="Expositor",$M$6,IF(D18="Organización",$M$7,IF(D18="Evaluador",$M$8,0)))) -> 0 | I18: =IF(F18="Resumen",IF(H18=0,$Q$5,$Q$6),IF(F18="Trabajo Extendido",IF(H18=0,$Q$7,$Q$8),IF(F18="Trabajo Completo",IF(H18=0,$Q$9,$Q$10),0))) -> 0 | J18: =E18+I18 -> 0 | O18: >5 | P18: 3
B19: 2 | E19: =IF(D19="Asistente",$M$5,IF(D19="Expositor",$M$6,IF(D19="Organización",$M$7,IF(D19="Evaluador",$M$8,0)))) -> 0 | I19: =IF(F19="Resumen",IF(H19=0,$Q$5,$Q$6),IF(F19="Trabajo Extendido",IF(H19=0,$Q$7,$Q$8),IF(F19="Trabajo Completo",IF(H19=0,$Q$9,$Q$10),0))) -> 0 | J19: =E19+I19 -> 0
B20: 2 | E20: =IF(D20="Asistente",$M$5,IF(D20="Expositor",$M$6,IF(D20="Organización",$M$7,IF(D20="Evaluador",$M$8,0)))) -> 0 | I20: =IF(F20="Resumen",IF(H20=0,$Q$5,$Q$6),IF(F20="Trabajo Extendido",IF(H20=0,$Q$7,$Q$8),IF(F20="Trabajo Completo",IF(H20=0,$Q$9,$Q$10),0))) -> 0 | J20: =E20+I20 -> 0
B21: 2 | E21: =IF(D21="Asistente",$M$5,IF(D21="Expositor",$M$6,IF(D21="Organización",$M$7,IF(D21="Evaluador",$M$8,0)))) -> 0 | I21: =IF(F21="Resumen",IF(H21=0,$Q$5,$Q$6),IF(F21="Trabajo Extendido",IF(H21=0,$Q$7,$Q$8),IF(F21="Trabajo Completo",IF(H21=0,$Q$9,$Q$10),0))) -> 0 | J21: =E21+I21 -> 0
B22: 2 | E22: =IF(D22="Asistente",$M$5,IF(D22="Expositor",$M$6,IF(D22="Organización",$M$7,IF(D22="Evaluador",$M$8,0)))) -> 0 | I22: =IF(F22="Resumen",IF(H22=0,$Q$5,$Q$6),IF(F22="Trabajo Extendido",IF(H22=0,$Q$7,$Q$8),IF(F22="Trabajo Completo",IF(H22=0,$Q$9,$Q$10),0))) -> 0 | J22: =E22+I22 -> 0
I23: PD52 | J23: =SUM(J17:J22) -> 4
I24: AD52 | J24: =IF(J23>5,3,IF(J23>1,1,0)) -> 1
B26: Año | C26: Evento | D26: Participación | F26: Presentación | J26: dei3
B27: p | D27: Tipo | E27: Vpai | F27: Tipo | G27: Título | H27: ´Referato | I27: Valor
B28: 3 | E28: =IF(D28="Asistente",$M$5,IF(D28="Expositor",$M$6,IF(D28="Organización",$M$7,IF(D28="Evaluador",$M$8,0)))) -> 0 | I28: =IF(F28="Resumen",IF(H28=0,$Q$5,$Q$6),IF(F28="Trabajo Extendido",IF(H28=0,$Q$7,$Q$8),IF(F28="Trabajo Completo",IF(H28=0,$Q$9,$Q$10),0))) -> 0 | J28: =E28+I28 -> 0
B29: 3 | E29: =IF(D29="Asistente",$M$5,IF(D29="Expositor",$M$6,IF(D29="Organización",$M$7,IF(D29="Evaluador",$M$8,0)))) -> 0 | I29: =IF(F29="Resumen",IF(H29=0,$Q$5,$Q$6),IF(F29="Trabajo Extendido",IF(H29=0,$Q$7,$Q$8),IF(F29="Trabajo Completo",IF(H29=0,$Q$9,$Q$10),0))) -> 0 | J29: =E29+I29 -> 0
B30: 3 | E30: =IF(D30="Asistente",$M$5,IF(D30="Expositor",$M$6,IF(D30="Organización",$M$7,IF(D30="Evaluador",$M$8,0)))) -> 0 | I30: =IF(F30="Resumen",IF(H30=0,$Q$5,$Q$6),IF(F30="Trabajo Extendido",IF(H30=0,$Q$7,$Q$8),IF(F30="Trabajo Completo",IF(H30=0,$Q$9,$Q$10),0))) -> 0 | J30: =E30+I30 -> 0
B31: 3 | E31: =IF(D31="Asistente",$M$5,IF(D31="Expositor",$M$6,IF(D31="Organización",$M$7,IF(D31="Evaluador",$M$8,0)))) -> 0 | I31: =IF(F31="Resumen",IF(H31=0,$Q$5,$Q$6),IF(F31="Trabajo Extendido",IF(H31=0,$Q$7,$Q$8),IF(F31="Trabajo Completo",IF(H31=0,$Q$9,$Q$10),0))) -> 0 | J31: =E31+I31 -> 0
B32: 3 | E32: =IF(D32="Asistente",$M$5,IF(D32="Expositor",$M$6,IF(D32="Organización",$M$7,IF(D32="Evaluador",$M$8,0)))) -> 0 | I32: =IF(F32="Resumen",IF(H32=0,$Q$5,$Q$6),IF(F32="Trabajo Extendido",IF(H32=0,$Q$7,$Q$8),IF(F32="Trabajo Completo",IF(H32=0,$Q$9,$Q$10),0))) -> 0 | J32: =E32+I32 -> 0
B33: 3 | E33: =IF(D33="Asistente",$M$5,IF(D33="Expositor",$M$6,IF(D33="Organización",$M$7,IF(D33="Evaluador",$M$8,0)))) -> 0 | I33: =IF(F33="Resumen",IF(H33=0,$Q$5,$Q$6),IF(F33="Trabajo Extendido",IF(H33=0,$Q$7,$Q$8),IF(F33="Trabajo Completo",IF(H33=0,$Q$9,$Q$10),0))) -> 0 | J33: =E33+I33 -> 0
I34: PD53 | J34: =SUM(J28:J33) -> 0
I35: AD53 | J35: =IF(J34>5,3,IF(J34>1,1,0)) -> 0
B37: Año | C37: Evento | D37: Participación | F37: Presentación | J37: dei4
B38: p | D38: Tipo | E38: Vpai | F38: Tipo | G38: Título | H38: ´Referato | I38: Valor
B39: 4 | C39: Coloquio | D39: Asistente | E39: =IF(D39="Asistente",$M$5,IF(D39="Expositor",$M$6,IF(D39="Organización",$M$7,IF(D39="Evaluador",$M$8,0)))) -> 1 | F39: Resumen | G39: El Pronóstico | H39: 1 | I39: =IF(F39="Resumen",IF(H39=0,$Q$5,$Q$6),IF(F39="Trabajo Extendido",IF(H39=0,$Q$7,$Q$8),IF(F39="Trabajo Completo",IF(H39=0,$Q$9,$Q$10),0))) -> 3 | J39: =E39+I39 -> 4
B40: 4 | C40: UNCUYO | D40: Expositor | E40: =IF(D40="Asistente",$M$5,IF(D40="Expositor",$M$6,IF(D40="Organización",$M$7,IF(D40="Evaluador",$M$8,0)))) -> 3 | F40: Trabajo Extendido | G40: El Pronóstico | H40: 1 | I40: =IF(F40="Resumen",IF(H40=0,$Q$5,$Q$6),IF(F40="Trabajo Extendido",IF(H40=0,$Q$7,$Q$8),IF(F40="Trabajo Completo",IF(H40=0,$Q$9,$Q$10),0))) -> 5 | J40: =E40+I40 -> 8
B41: 4 | C41: FGDGG | D41: Expositor | E41: =IF(D41="Asistente",$M$5,IF(D41="Expositor",$M$6,IF(D41="Organización",$M$7,IF(D41="Evaluador",$M$8,0)))) -> 3 | F41: Trabajo Completo | G41: El Pronóstico | H41: 1 | I41: =IF(F41="Resumen",IF(H41=0,$Q$5,$Q$6),IF(F41="Trabajo Extendido",IF(H41=0,$Q$7,$Q$8),IF(F41="Trabajo Completo",IF(H41=0,$Q$9,$Q$10),0))) -> 8 | J41: =E41+I41 -> 11
B42: 4 | C42: SSE | D42: Organización | E42: =IF(D42="Asistente",$M$5,IF(D42="Expositor",$M$6,IF(D42="Organización",$M$7,IF(D42="Evaluador",$M$8,0)))) -> 4 | I42: =IF(F42="Resumen",IF(H42=0,$Q$5,$Q$6),IF(F42="Trabajo Extendido",IF(H42=0,$Q$7,$Q$8),IF(F42="Trabajo Completo",IF(H42=0,$Q$9,$Q$10),0))) -> 0 | J42: =E42+I42 -> 4
B43: 4 | C43: pppp | D43: Evaluador | E43: =IF(D43="Asistente",$M$5,IF(D43="Expositor",$M$6,IF(D43="Organización",$M$7,IF(D43="Evaluador",$M$8,0)))) -> 5 | I43: =IF(F43="Resumen",IF(H43=0,$Q$5,$Q$6),IF(F43="Trabajo Extendido",IF(H43=0,$Q$7,$Q$8),IF(F43="Trabajo Completo",IF(H43=0,$Q$9,$Q$10),0))) -> 0 | J43: =E43+I43 -> 5
B44: 4 | E44: =IF(D44="Asistente",$M$5,IF(D44="Expositor",$M$6,IF(D44="Organización",$M$7,IF(D44="Evaluador",$M$8,0)))) -> 0 | I44: =IF(F44="Resumen",IF(H44=0,$Q$5,$Q$6),IF(F44="Trabajo Extendido",IF(H44=0,$Q$7,$Q$8),IF(F44="Trabajo Completo",IF(H44=0,$Q$9,$Q$10),0))) -> 0 | J44: =E44+I44 -> 0
...

Sheet AD6
B2: AD6: Proyectos en docencia acreditados | H2: Cuadro 2.4.6.1: Ponderación según participación en el proyecto | K2: Cuadro 2.4.6.2: Caracterización de AD6
B3: Año | C3: Proyecto | D3: Normativa | E3: Tipo de participación | F3: dpyip | H3: Tipo de Participación | I3: dpy | K3: PD6 | L3: Categoría AD6
B4: 1 | C4: Chinche | D4: N°560/236-D | E4: Director | F4: =IF(E4="Director",I$4,IF(E4="Codirector",$I$5,IF(E4="Participante",$I$6,IF(E4="Evaluador",$I$7,0)))) -> 8 | H4: Director | I4: 8 | K4: 0 | L4: 0
B5: 1 | C5: Pi | D5: N°560/236-D | E5: Codirector | F5: =IF(E5="Director",I$4,IF(E5="Codirector",$I$5,IF(E5="Participante",$I$6,IF(E5="Evaluador",$I$7,0)))) -> 5 | H5: Codirector | I5: 5 | K5: 1 - 8 | L5: 1
B6: 1 | C6: Pipi | D6: N°560/236-D | E6: Participante | F6: =IF(E6="Director",I$4,IF(E6="Codirector",$I$5,IF(E6="Participante",$I$6,IF(E6="Evaluador",$I$7,0)))) -> 1 | H6: Participante | I6: 1 | K6: >8 | L6: 3
B7: 1 | C7: Titi | D7: N°560/236-D | E7: Evaluador | F7: =IF(E7="Director",I$4,IF(E7="Codirector",$I$5,IF(E7="Participante",$I$6,IF(E7="Evaluador",$I$7,0)))) -> 5 | H7: Evaluador | I7: 5
E8: PD61 | F8: =SUM(F4:F7) -> 19
E9: AD61 | F9: =IF(F8>8,3,IF(F8>0,1,0)) -> 3
B11: Año | C11: Proyecto | D11: Normativa | E11: Tipo de participación | F11: dpyip
B12: 2 | C12: N | D12: N°560/236-D | E12: Director | F12: =IF(E12="Director",I$4,IF(E12="Codirector",$I$5,IF(E12="Participante",$I$6,IF(E12="Evaluador",$I$7,0)))) -> 8
B13: 2 | C13: S | D13: N°560/236-D | E13: Codirector | F13: =IF(E13="Director",I$4,IF(E13="Codirector",$I$5,IF(E13="Participante",$I$6,IF(E13="Evaluador",$I$7,0)))) -> 5
B14: 2 | F14: =IF(E14="Director",I$4,IF(E14="Codirector",$I$5,IF(E14="Participante",$I$6,IF(E14="Evaluador",$I$7,0)))) -> 0
B15: 2 | F15: =IF(E15="Director",I$4,IF(E15="Codirector",$I$5,IF(E15="Participante",$I$6,IF(E15="Evaluador",$I$7,0)))) -> 0
E16: PD62 | F16: =SUM(F12:F15) -> 13
E17: AD62 | F17: =IF(F16>8,3,IF(F16>0,1,0)) -> 3
B20: Año | C20: Proyecto | D20: Normativa | E20: Tipo de participación | F20: dpyip
B21: 3 | C21: Q | D21: N°560/236-D | E21: Participante | F21: =IF(E21="Director",I$4,IF(E21="Codirector",$I$5,IF(E21="Participante",$I$6,IF(E21="Evaluador",$I$7,0)))) -> 1
B22: 3 | F22: =IF(E22="Director",I$4,IF(E22="Codirector",$I$5,IF(E22="Participante",$I$6,IF(E22="Evaluador",$I$7,0)))) -> 0
B23: 3 | F23: =IF(E23="Director",I$4,IF(E23="Codirector",$I$5,IF(E23="Participante",$I$6,IF(E23="Evaluador",$I$7,0)))) -> 0
B24: 3 | F24: =IF(E24="Director",I$4,IF(E24="Codirector",$I$5,IF(E24="Participante",$I$6,IF(E24="Evaluador",$I$7,0)))) -> 0
E25: PD63 | F25: =SUM(F21:F24) -> 1
E26: AD63 | F26: =IF(F25>8,3,IF(F25>0,1,0)) -> 1
B28: Año | C28: Proyecto | D28: Normativa | E28: Tipo de participación | F28: dpyip
B29: 4 | F29: =IF(E29="Director",I$4,IF(E29="Codirector",$I$5,IF(E29="Participante",$I$6,IF(E29="Evaluador",$I$7,0)))) -> 0
B30: 4 | F30: =IF(E30="Director",I$4,IF(E30="Codirector",$I$5,IF(E30="Participante",$I$6,IF(E30="Evaluador",$I$7,0)))) -> 0
B31: 4 | F31: =IF(E31="Director",I$4,IF(E31="Codirector",$I$5,IF(E31="Participante",$I$6,IF(E31="Evaluador",$I$7,0)))) -> 0
B32: 4 | F32: =IF(E32="Director",I$4,IF(E32="Codirector",$I$5,IF(E32="Participante",$I$6,IF(E32="Evaluador",$I$7,0)))) -> 0
E33: PD64 | F33: =SUM(F29:F32) -> 0
E34: AD64 | F34: =IF(F33>8,3,IF(F33>0,1,0)) -> 0

Sheet AD7
B2: AD7: Formación de recursos humanos | G2: Cuadro 2.4.7.1: Valoración según participación en el proyecto | J2: Cuadro 2.4.7.2: Caracterización de AD7
B3: Año | C3: Categoría | D3: Apellido y Nombre | E3: dfip | G3: Categoría | H3: Valoración | J3: PD7 | K3: Categoría AD7
B4: 1 | C4: Docente | D4: José | E4: =IF(C4="Docente",$H$4,IF(C4="Adscripto",$H$5,IF(C4="Pasante",$H$6,IF(C4="Concurrencia",$H$7,0)))) -> 10 | G4: Docente | H4: 10 | J4: 0 | K4: 0
B5: 1 | C5: Adscripto | D5: Tony | E5: =IF(C5="Docente",$H$4,IF(C5="Adscripto",$H$5,IF(C5="Pasante",$H$6,IF(C5="Concurrencia",$H$7,0)))) -> 5 | G5: Adscripto | H5: 5 | J5: 1 -15 | K5: 1
B6: 1 | C6: Pasante | D6: Mónica | E6: =IF(C6="Docente",$H$4,IF(C6="Adscripto",$H$5,IF(C6="Pasante",$H$6,IF(C6="Concurrencia",$H$7,0)))) -> 3 | G6: Pasante | H6: 3 | J6: >15 | K6: 3
B7: 1 | C7: Concurrencia | D7: Josefa | E7: =IF(C7="Docente",$H$4,IF(C7="Adscripto",$H$5,IF(C7="Pasante",$H$6,IF(C7="Concurrencia",$H$7,0)))) -> 3 | G7: Concurrencia | H7: 3
B8: 1 | E8: =IF(C8="Docente",$H$4,IF(C8="Adscripto",$H$5,IF(C8="Pasante",$H$6,IF(C8="Concurrencia",$H$7,0)))) -> 0
D9: PD71 | E9: =SUM(E4:E8) -> 21
D10: AD71 | E10: =IF(E9>15,3,IF(E9>0,1,0)) -> 3
B13: Año | C13: Categoría | D13: Apellido y Nombre | E13: dfip
B14: 2 | C14: Docente | D14: José | E14: =IF(C14="Docente",$H$4,IF(C14="Adscripto",$H$5,IF(C14="Pasante",$H$6,IF(C14="Concurrencia",$H$7,0)))) -> 10
B15: 2 | C15: Docente | D15: Tony | E15: =IF(C15="Docente",$H$4,IF(C15="Adscripto",$H$5,IF(C15="Pasante",$H$6,IF(C15="Concurrencia",$H$7,0)))) -> 10
B16: 2 | C16: Docente | D16: Mónica | E16: =IF(C16="Docente",$H$4,IF(C16="Adscripto",$H$5,IF(C16="Pasante",$H$6,IF(C16="Concurrencia",$H$7,0)))) -> 10
B17: 2 | C17: Concurrencia | D17: Josefa | E17: =IF(C17="Docente",$H$4,IF(C17="Adscripto",$H$5,IF(C17="Pasante",$H$6,IF(C17="Concurrencia",$H$7,0)))) -> 3
B18: 2 | E18: =IF(C18="Docente",$H$4,IF(C18="Adscripto",$H$5,IF(C18="Pasante",$H$6,IF(C18="Concurrencia",$H$7,0)))) -> 0
D19: PD72 | E19: =SUM(E14:E18) -> 33
D20: AD72 | E20: =IF(E19>15,3,IF(E19>0,1,0)) -> 3
B22: Año | C22: Categoría | D22: Apellido y Nombre | E22: dfip
B23: 3 | C23: Docente | D23: José | E23: =IF(C23="Docente",$H$4,IF(C23="Adscripto",$H$5,IF(C23="Pasante",$H$6,IF(C23="Concurrencia",$H$7,0)))) -> 10
B24: 3 | E24: =IF(C24="Docente",$H$4,IF(C24="Adscripto",$H$5,IF(C24="Pasante",$H$6,IF(C24="Concurrencia",$H$7,0)))) -> 0
B25: 3 | E25: =IF(C25="Docente",$H$4,IF(C25="Adscripto",$H$5,IF(C25="Pasante",$H$6,IF(C25="Concurrencia",$H$7,0)))) -> 0
B26: 3 | E26: =IF(C26="Docente",$H$4,IF(C26="Adscripto",$H$5,IF(C26="Pasante",$H$6,IF(C26="Concurrencia",$H$7,0)))) -> 0
B27: 3 | E27: =IF(C27="Docente",$H$4,IF(C27="Adscripto",$H$5,IF(C27="Pasante",$H$6,IF(C27="Concurrencia",$H$7,0)))) -> 0
D28: PD73 | E28: =SUM(E23:E27) -> 10
D29: AD73 | E29: =IF(E28>15,3,IF(E28>0,1,0)) -> 1
B31: Año | C31: Categoría | D31: Apellido y Nombre | E31: dfip
B32: 4 | E32: =IF(C32="Docente",$H$4,IF(C32="Adscripto",$H$5,IF(C32="Pasante",$H$6,IF(C32="Concurrencia",$H$7,0)))) -> 0
B33: 4 | E33: =IF(C33="Docente",$H$4,IF(C33="Adscripto",$H$5,IF(C33="Pasante",$H$6,IF(C33="Concurrencia",$H$7,0)))) -> 0
B34: 4 | E34: =IF(C34="Docente",$H$4,IF(C34="Adscripto",$H$5,IF(C34="Pasante",$H$6,IF(C34="Concurrencia",$H$7,0)))) -> 0
B35: 4 | E35: =IF(C35="Docente",$H$4,IF(C35="Adscripto",$H$5,IF(C35="Pasante",$H$6,IF(C35="Concurrencia",$H$7,0)))) -> 0
B36: 4 | E36: =IF(C36="Docente",$H$4,IF(C36="Adscripto",$H$5,IF(C36="Pasante",$H$6,IF(C36="Concurrencia",$H$7,0)))) -> 0
D37: PD74 | E37: =SUM(E32:E36) -> 0
D38: AD74 | E38: =IF(E37>15,3,IF(E37>0,1,0)) -> 0

Sheet AD8
B2: AD8: Producción de materiales pedagógicos | K2: Cuadro 2.4.8.1: Valoración según material pedagógico
B3: Año | C3: Carrera | D3: Espacio curricular | E3: Material | F3: Valor Material | G3: Tarea | H3: Valor Tarea | I3: dmpip | K3: Material | L3: Valor | N3: Cuadro 2.4.8.3: Caracterización de AD8
B4: 1 | C4: IA | D4: Estadística y Diseño Experimental | E4: Apuntes de Clase | F4: =IF(E4="Apuntes de clase",L$4,IF(E4="Trabajo Práctico",$L$5,IF(E4="Entorno Virtual",$L$6,0))) -> 8 | G4: Actualización | H4: =IF(G4="Desarrollo",$L$12,IF(G4="Actualización",$L$13,0)) -> 1 | I4: =F4*H4 -> 8 | K4: Apuntes de clase | L4: 8 | N4: PD8 | O4: Categoría AD8
B5: 1 | C5: IA | D5: Estadística y Diseño Experimental | E5: Trabajo Práctico | F5: =IF(E5="Apuntes de clase",L$4,IF(E5="Trabajo Práctico",$L$5,IF(E5="Entorno Virtual",$L$6,0))) -> 5 | G5: Desarrollo | H5: =IF(G5="Desarrollo",$L$12,IF(G5="Actualización",$L$13,0)) -> 5 | I5: =F5*H5 -> 25 | K5: Trabajo Práctico | L5: 5 | N5: 0-19 | O5: 0
B6: 1 | C6: LB | D6: Estadistica Aplicada | E6: Entorno Virtual | F6: =IF(E6="Apuntes de clase",L$4,IF(E6="Trabajo Práctico",$L$5,IF(E6="Entorno Virtual",$L$6,0))) -> 8 | G6: Actualización | H6: =IF(G6="Desarrollo",$L$12,IF(G6="Actualización",$L$13,0)) -> 1 | I6: =F6*H6 -> 8 | K6: Entorno Virtual | L6: 8 | N6: 20 | O6: 1
B7: 1 | F7: =IF(E7="Apuntes de clase",L$4,IF(E7="Trabajo Práctico",$L$5,IF(E7="Entorno Virtual",$L$6,0))) -> 0 | H7: =IF(G7="Desarrollo",$L$12,IF(G7="Actualización",$L$13,0)) -> 0 | I7: =F7*H7 -> 0 | N7: >20 | O7: 3
B8: 1 | F8: =IF(E8="Apuntes de clase",L$4,IF(E8="Trabajo Práctico",$L$5,IF(E8="Entorno Virtual",$L$6,0))) -> 0 | H8: =IF(G8="Desarrollo",$L$12,IF(G8="Actualización",$L$13,0)) -> 0 | I8: =F8*H8 -> 0
H9: PD81 | I9: =SUM(I4:I8) -> 41
H10: AD81 | I10: =IF(I9>20,3,IF(I9=20,1,0)) -> 3 | K10: Cuadro 2.4.8.2: Valoración según tarea
K11: Tarea | L11: Valor
K12: Desarrollo | L12: 5
B13: AD8: Producción de materiales pedagógicos | K13: Actualización | L13: 1
B14: Año | C14: Carrera | D14: Espacio curricular | E14: Material | F14: Valor Material | G14: Tarea | H14: Valor Tarea | I14: dmpip
B15: 2 | C15: IA | D15: Estadística y Diseño Experimental | E15: Apuntes de Clase | F15: =IF(E15="Apuntes de clase",L$4,IF(E15="Trabajo Práctico",$L$5,IF(E15="Entorno Virtual",$L$6,0))) -> 8 | G15: Actualización | H15: =IF(G15="Desarrollo",5,IF(G15="Actualización",1,0)) -> 1 | I15: =F15*H15 -> 8
B16: 2 | C16: IA | D16: Estadística y Diseño Experimental | E16: Trabajo Práctico | F16: =IF(E16="Apuntes de clase",L$4,IF(E16="Trabajo Práctico",$L$5,IF(E16="Entorno Virtual",$L$6,0))) -> 5 | G16: Actualización | H16: =IF(G16="Desarrollo",5,IF(G16="Actualización",1,0)) -> 1 | I16: =F16*H16 -> 5
B17: 2 | C17: LB | D17: Estadistica Aplicada | E17: Entorno Virtual | F17: =IF(E17="Apuntes de clase",L$4,IF(E17="Trabajo Práctico",$L$5,IF(E17="Entorno Virtual",$L$6,0))) -> 8 | G17: Actualización | H17: =IF(G17="Desarrollo",5,IF(G17="Actualización",1,0)) -> 1 | I17: =F17*H17 -> 8
B18: 2 | F18: =IF(E18="Apuntes de clase",L$4,IF(E18="Trabajo Práctico",$L$5,IF(E18="Entorno Virtual",$L$6,0))) -> 0 | H18: =IF(G18="Desarrollo",5,IF(G18="Actualización",1,0)) -> 0 | I18: =F18*H18 -> 0
B19: 2 | F19: =IF(E19="Apuntes de clase",L$4,IF(E19="Trabajo Práctico",$L$5,IF(E19="Entorno Virtual",$L$6,0))) -> 0 | H19: =IF(G19="Desarrollo",5,IF(G19="Actualización",1,0)) -> 0 | I19: =F19*H19 -> 0
H20: PD82 | I20: =SUM(I15:I19) -> 21
H21: AD82 | I21: =IF(I20>20,3,IF(I20=20,1,0)) -> 3
B24: AD8: Producción de materiales pedagógicos
B25: Año | C25: Carrera | D25: Espacio curricular | E25: Material | F25: Valor Material | G25: Tarea | H25: Valor Tarea | I25: dmpip
B26: 3 | C26: IA | D26: Estadística y Diseño Experimental | E26: Apuntes de Clase | F26: =IF(E26="Apuntes de clase",L$4,IF(E26="Trabajo Práctico",$L$5,IF(E26="Entorno Virtual",$L$6,0))) -> 8 | G26: Actualización | H26: =IF(G26="Desarrollo",$L$12,IF(G26="Actualización",$L$13,0)) -> 1 | I26: =F26*H26 -> 8
B27: 3 | C27: IA | D27: Estadística y Diseño Experimental | E27: Trabajo Práctico | F27: =IF(E27="Apuntes de clase",L$4,IF(E27="Trabajo Práctico",$L$5,IF(E27="Entorno Virtual",$L$6,0))) -> 5 | G27: Actualización | H27: =IF(G27="Desarrollo",$L$12,IF(G27="Actualización",$L$13,0)) -> 1 | I27: =F27*H27 -> 5
B28: 3 | F28: =IF(E28="Apuntes de clase",L$4,IF(E28="Trabajo Práctico",$L$5,IF(E28="Entorno Virtual",$L$6,0))) -> 0 | H28: =IF(G28="Desarrollo",$L$12,IF(G28="Actualización",$L$13,0)) -> 0 | I28: =F28*H28 -> 0
B29: 3 | F29: =IF(E29="Apuntes de clase",L$4,IF(E29="Trabajo Práctico",$L$5,IF(E29="Entorno Virtual",$L$6,0))) -> 0 | H29: =IF(G29="Desarrollo",$L$12,IF(G29="Actualización",$L$13,0)) -> 0 | I29: =F29*H29 -> 0
B30: 3 | F30: =IF(E30="Apuntes de clase",L$4,IF(E30="Trabajo Práctico",$L$5,IF(E30="Entorno Virtual",$L$6,0))) -> 0 | H30: =IF(G30="Desarrollo",$L$12,IF(G30="Actualización",$L$13,0)) -> 0 | I30: =F30*H30 -> 0
H31: PD83 | I31: =SUM(I26:I30) -> 13
H32: AD83 | I32: =IF(I31>20,3,IF(I31=20,1,0)) -> 0
B34: AD8: Producción de materiales pedagógicos
B35: Año | C35: Carrera | D35: Espacio curricular | E35: Material | F35: Valor Material | G35: Tarea | H35: Valor Tarea | I35: dmpip
B36: 4 | E36: Trabajo Práctico | F36: =IF(E36="Apuntes de clase",L$4,IF(E36="Trabajo Práctico",$L$5,IF(E36="Entorno Virtual",$L$6,0))) -> 5 | G36: Actualización | H36: =IF(G36="Desarrollo",5,IF(G36="Actualización",1,0)) -> 1 | I36: =F36*H36 -> 5
B37: 4 | F37: =IF(E37="Apuntes de clase",L$4,IF(E37="Trabajo Práctico",$L$5,IF(E37="Entorno Virtual",$L$6,0))) -> 0 | H37: =IF(G37="Desarrollo",5,IF(G37="Actualización",1,0)) -> 0 | I37: =F37*H37 -> 0
B38: 4 | F38: =IF(E38="Apuntes de clase",L$4,IF(E38="Trabajo Práctico",$L$5,IF(E38="Entorno Virtual",$L$6,0))) -> 0 | H38: =IF(G38="Desarrollo",5,IF(G38="Actualización",1,0)) -> 0 | I38: =F38*H38 -> 0
B39: 4 | F39: =IF(E39="Apuntes de clase",L$4,IF(E39="Trabajo Práctico",$L$5,IF(E39="Entorno Virtual",$L$6,0))) -> 0 | H39: =IF(G39="Desarrollo",5,IF(G39="Actualización",1,0)) -> 0 | I39: =F39*H39 -> 0
B40: 4 | F40: =IF(E40="Apuntes de clase",L$4,IF(E40="Trabajo Práctico",$L$5,IF(E40="Entorno Virtual",$L$6,0))) -> 0 | H40: =IF(G40="Desarrollo",5,IF(G40="Actualización",1,0)) -> 0 | I40: =F40*H40 -> 0
H41: PD84 | I41: =SUM(I36:I40) -> 5
H42: AD84 | I42: =IF(I41>20,3,IF(I41=20,1,0)) -> 0

Sheet Puntaje
B2: Tabla 3: | C2: Puntajes totales obtenidos en cada año, para las diferentes dimensiones de la actividad docente declarada | M2: Cuadro 2.2: | N2: Umbrales Básicos (UB) para las dimensiones en docencia según categoría y dedicación
B3: Año | C3: PD1 | D3: PD2 | E3: PD3 | F3: PD4 | G3: PD5 | H3: PD6 | I3: PD7 | J3: PD8 | K3: Puntaje | M3: Categoría (j) | N3: Dedicación (l) | O3: UBD1 | P3: UBD2 | Q3: UBD3 | R3: UBD4 | S3: UBD5 | T3: UBD6 | U3: UBD7 | V3: UBD8 | W3: UBDjl
B4: 1 | C4: ='AD1'!G13 -> 6 | D4: ='AD2'!P8 -> 2.8 | E4: ='AD3'!I14 -> 13.748148 | F4: ='AD4'!H8 -> 12.1 | G4: ='AD5'!J12 -> 32 | H4: ='AD6'!F8 -> 19 | I4: ='AD7'!E9 -> 21 | J4: ='AD8'!I9 -> 41 | K4: =SUM(C4:J4) -> 147.64815 | M4: T | N4: EX | O4: 6 | P4: 1 | Q4: 1 | R4: 1 | S4: 1 | T4: 1 | U4: 1 | V4: 19 | W4: =SUM(O4:V4) -> 31
B5: 2 | C5: ='AD1'!J13 -> 6.5 | D5: ='AD2'!P16 -> 1.7 | E5: ='AD3'!I27 -> 13.048148 | F5: ='AD4'!H17 -> 1.1 | G5: ='AD5'!J23 -> 4 | H5: ='AD6'!F16 -> 13 | I5: ='AD7'!E19 -> 33 | J5: ='AD8'!I20 -> 21 | K5: =SUM(C5:J5) -> 93.348148 | M5: AS | N5: EX | O5: 6 | P5: 1 | Q5: 1 | R5: 1 | S5: 1 | T5: 1 | U5: 1 | V5: 19 | W5: =SUM(O5:V5) -> 31
B6: 3 | C6: ='AD1'!M13 -> 9.5 | D6: ='AD2'!P24 -> 2.4 | E6: ='AD3'!I41 -> 13.048148 | F6: ='AD4'!H27 -> 3.5 | G6: ='AD5'!J34 -> 0 | H6: ='AD6'!F25 -> 1 | I6: ='AD7'!E28 -> 10 | J6: ='AD8'!I31 -> 13 | K6: =SUM(C6:J6) -> 52.448148 | M6: AJ | N6: EX | O6: 6 | P6: 1 | Q6: 1 | R6: 1 | S6: 1 | T6: 1 | U6: 1 | V6: 19 | W6: =SUM(O6:V6) -> 31
B7: 4 | C7: ='AD1'!P13 -> 14.5 | D7: ='AD2'!P32 -> 2.4 | E7: ='AD3'!I54 -> 13.131481 | F7: ='AD4'!H36 -> 3.5 | G7: ='AD5'!J45 -> 32 | H7: ='AD6'!F33 -> 0 | I7: ='AD7'!E37 -> 0 | J7: ='AD8'!I41 -> 5 | K7: =SUM(C7:J7) -> 70.531481 | M7: JTP | N7: EX | O7: 3 | P7: 1 | Q7: 1 | R7: 1 | S7: 1 | T7: 1 | U7: 1 | V7: 19 | W7: =SUM(O7:V7) -> 28
M8: AY1 | N8: EX | O8: 1 | P8: 1 | Q8: 1 | R8: 1 | S8: 1 | T8: 1 | U8: 1 | V8: 19 | W8: =SUM(O8:V8) -> 26
B9: PDD | C9: Identificación | M9: T | N9: SE | O9: 6 | P9: 1 | Q9: 1 | R9: 1 | S9: 1 | T9: 1 | U9: 1 | V9: 19 | W9: =SUM(O9:V9) -> 31
B10: PD1 | C10: Formación Académica | M10: AS | N10: SE | O10: 6 | P10: 1 | Q10: 1 | R10: 1 | S10: 1 | T10: 1 | U10: 1 | V10: 19 | W10: =SUM(O10:V10) -> 31
B11: PD2 | C11: Actividad y Capacitación | M11: AJ | N11: SE | O11: 6 | P11: 1 | Q11: 1 | R11: 1 | S11: 1 | T11: 1 | U11: 1 | V11: 19 | W11: =SUM(O11:V11) -> 31
B12: PD3 | C12: Docencia en pregrado y grado | M12: JTP | N12: SE | O12: 3 | P12: 1 | Q12: 1 | R12: 1 | S12: 1 | T12: 1 | U12: 1 | V12: 19 | W12: =SUM(O12:V12) -> 28
B13: PD4 | C13: Docencia en posgrado | M13: AY1 | N13: SE | O13: 1 | P13: 1 | Q13: 1 | R13: 1 | S13: 1 | T13: 1 | U13: 1 | V13: 19 | W13: =SUM(O13:V13) -> 26
B14: PD5 | C14: Participación en reuniones | M14: T | N14: DS | O14: 6 | P14: 1 | Q14: 1 | R14: 1 | S14: 1 | T14: 1 | U14: 1 | V14: 19 | W14: =SUM(O14:V14) -> 31
B15: PD6 | C15: Proyectos en docencia | M15: AS | N15: DS | O15: 6 | P15: 1 | Q15: 1 | R15: 1 | S15: 1 | T15: 1 | U15: 1 | V15: 19 | W15: =SUM(O15:V15) -> 31
B16: PD7 | C16: Formación en recursos | M16: AJ | N16: DS | O16: 6 | P16: 1 | Q16: 1 | R16: 1 | S16: 1 | T16: 1 | U16: 1 | V16: 19 | W16: =SUM(O16:V16) -> 31
B17: PD8 | C17: Producción en material pedagógico | M17: JTP | N17: DS | O17: 3 | P17: 1 | Q17: 1 | R17: 1 | S17: 1 | T17: 1 | U17: 1 | V17: 19 | W17: =SUM(O17:V17) -> 28
M18: AY1 | N18: DS | O18: 1 | P18: 1 | Q18: 1 | R18: 1 | S18: 1 | T18: 1 | U18: 1 | V18: 19 | W18: =SUM(O18:V18) -> 26
M19: AY2 | N19: DS | O19: 0 | P19: 1 | Q19: 1 | R19: 1 | S19: 1 | T19: 1 | U19: 1 | V19: 19 | W19: =SUM(O19:V19) -> 25
