Workbook

Sheet AI
V1: Tabla 2: | W1: Umbral básico de investigación fijado
B2: Tabla 1: | C2: Ïndice de actividad en investigación parcial y final durante un período de 4 años | V2: seún la categoría y dedicación del docente
B3: Período | C3: Categoría | D3: Dedicación | E3: Licencias | G3: Corrección temporal | I3: Actividad Investigación | R3: Umbral | S3: Índice de Actividad | T3: Índice de Actividad | V3: Categoría | W3: Dedicación | X3: Umbral Básico
E4: c/goce sueldo | F4: s/goce sueldo | G4: Tiempo | H4: factor de | Q4: Puntaje | R4: Básico | S4: en Investigación | T4: en Investigación | V4: (j) | W4: (k) | X4: UBIjk
B5: k | E5: (meses) | F5: (meses) | G5: (años) | H5: corrección | I5: Dimensiones | O5: AIp | P5: AIp | R5: Investigación | S5: Parcial | T5: en k años | V5: T | W5: EX | X5: =Puntaje!S4 -> 88
B6: (años) | C6: (j) | D6: (k) | E6: (lcg) | F6: (lsg) | G6: (tp) | H6: fck | I6: AI1 | J6: AI2 | K6: AI3 | L6: AI4 | M6: AI5 | N6: AI6 | O6: Total | P6: Medio | Q6: PIpjl | R6: UBIpjl | S6: IA2pjl | T6: IA2kjl | V6: AS | W6: EX | X6: =Puntaje!S5 -> 88
B7: 1 | C7: AJ | D7: SE | E7: 5 | F7: 1 | G7: =1-(E7+F7)/12 -> 0.5 | H7: =B7/G7 -> 2 | I7: ='AI1'!D11 -> 1 | J7: ='AI2'!O23 -> 3 | K7: ='AI3'!G10 -> 3 | L7: ='AI4'!AB13 -> 3 | M7: ='AI5'!V11 -> 3 | N7: ='AI6'!Q13 -> 3 | O7: =SUM(I7:N7) -> 16 | P7: =O7/6 -> 2.6666667 | Q7: =Puntaje!I4 -> 644.25 | R7: =IF(AND(C7="T",D7="EX"),$X$5,IF(AND(C7="AS",D7="EX"),$X$6,IF(AND(C7="AJ",D7="EX"),$X$7,IF(AND(C7="JTP",D7="EX"),$X$8,IF(AND(C7="AY1",D7="EX"),$X9,IF(AND(C7="T",D7="SE"),$X$10,IF(AND(C7="AS",D7="SE"),$X$11,IF(AND(C7="AJ",D7="SE"),$X$12,IF(AND(C7="JTP",D7="SE"),$X$13,IF(AND(C7="AY1",D7="SE"),$X$14,IF(AND(C7="T",D7="DS"),$X$15,IF(AND(C7="AS",D7="DS"),X$16,IF(AND(C7="AJ",D7="DS"),$X$17,IF(AND(C7="JTP",D7="DS"),$X$18,IF(AND(C7="AY1",D7="DS"),$X$19,IF(AND(C7="AY2",D7="DS"),$X$20,0)))))))))))))))) -> 48 | S7: =Q7/R7/G7 -> 26.84375 | T7: =Q7/R7*H7 -> 26.84375 | V7: AJ | W7: EX | X7: =Puntaje!S6 -> 48
B8: 2 | C8: T | D8: SE | E8: 3 | F8: 0 | G8: =1-(E8+F8)/12 -> 0.75 | H8: =B8/SUM(G7:G8) -> 1.6 | I8: ='AI1'!D22 -> 0 | J8: ='AI2'!O23 -> 3 | K8: ='AI3'!G19 -> 1 | L8: ='AI4'!AB25 -> 0 | M8: ='AI5'!V22 -> 3 | N8: ='AI6'!Q26 -> 3 | O8: =SUM(I8:N8) -> 10 | P8: =O8/6 -> 1.6666667 | Q8: =Puntaje!I5 -> 297.15 | R8: =IF(AND(C8="T",D8="EX"),$X$5,IF(AND(C8="AS",D8="EX"),$X$6,IF(AND(C8="AJ",D8="EX"),$X$7,IF(AND(C8="JTP",D8="EX"),$X$8,IF(AND(C8="AY1",D8="EX"),$X10,IF(AND(C8="T",D8="SE"),$X$10,IF(AND(C8="AS",D8="SE"),$X$11,IF(AND(C8="AJ",D8="SE"),$X$12,IF(AND(C8="JTP",D8="SE"),$X$13,IF(AND(C8="AY1",D8="SE"),$X$14,IF(AND(C8="T",D8="DS"),$X$15,IF(AND(C8="AS",D8="DS"),X$16,IF(AND(C8="AJ",D8="DS"),$X$17,IF(AND(C8="JTP",D8="DS"),$X$18,IF(AND(C8="AY1",D8="DS"),$X$19,IF(AND(C8="AY2",D8="DS"),$X$20,0)))))))))))))))) -> 88 | S8: =Q8/R8/G8 -> 4.5022727 | T8: =SUM(Q7:Q8)/SUM(R7:R8)*H8 -> 11.075294 | V8: JTP | W8: EX | X8: =Puntaje!S7 -> 37
B9: 3 | C9: T | D9: EX | E9: 0 | F9: 0 | G9: =1-(E9+F9)/12 -> 1 | H9: =B9/SUM(G7:G9) -> 1.3333333 | I9: ='AI1'!D33 -> 1 | J9: ='AI2'!O34 -> 0 | K9: ='AI3'!G28 -> 3 | L9: ='AI4'!AB38 -> 0 | M9: ='AI5'!V34 -> 3 | N9: ='AI6'!Q40 -> 3 | O9: =SUM(I9:N9) -> 10 | P9: =O9/6 -> 1.6666667 | Q9: =Puntaje!I6 -> 208.1 | R9: =IF(AND(C9="T",D9="EX"),$X$5,IF(AND(C9="AS",D9="EX"),$X$6,IF(AND(C9="AJ",D9="EX"),$X$7,IF(AND(C9="JTP",D9="EX"),$X$8,IF(AND(C9="AY1",D9="EX"),$X11,IF(AND(C9="T",D9="SE"),$X$10,IF(AND(C9="AS",D9="SE"),$X$11,IF(AND(C9="AJ",D9="SE"),$X$12,IF(AND(C9="JTP",D9="SE"),$X$13,IF(AND(C9="AY1",D9="SE"),$X$14,IF(AND(C9="T",D9="DS"),$X$15,IF(AND(C9="AS",D9="DS"),X$16,IF(AND(C9="AJ",D9="DS"),$X$17,IF(AND(C9="JTP",D9="DS"),$X$18,IF(AND(C9="AY1",D9="DS"),$X$19,IF(AND(C9="AY2",D9="DS"),$X$20,0)))))))))))))))) -> 88 | S9: =Q9/R9/G9 -> 2.3647727 | T9: =SUM(Q7:Q9)/SUM(R7:R9)*H9 -> 6.8422619 | V9: AY1 | W9: EX | X9: =Puntaje!S8 -> 5
B10: 4 | C10: T | D10: EX | E10: 0 | F10: 0 | G10: =1-(E10+F10)/12 -> 1 | H10: =B10/SUM(G7:G10) -> 1.2307692 | I10: ='AI1'!D44 -> 1 | J10: ='AI2'!O45 -> 3 | K10: ='AI3'!G37 -> 3 | L10: ='AI4'!AB52 -> 3 | M10: ='AI5'!V45 -> 0 | N10: ='AI6'!Q54 -> 3 | O10: =SUM(I10:N10) -> 13 | P10: =O10/6 -> 2.1666667 | Q10: =Puntaje!I7 -> 250.25 | R10: =IF(AND(C10="T",D10="EX"),$X$5,IF(AND(C10="AS",D10="EX"),$X$6,IF(AND(C10="AJ",D10="EX"),$X$7,IF(AND(C10="JTP",D10="EX"),$X$8,IF(AND(C10="AY1",D10="EX"),$X12,IF(AND(C10="T",D10="SE"),$X$10,IF(AND(C10="AS",D10="SE"),$X$11,IF(AND(C10="AJ",D10="SE"),$X$12,IF(AND(C10="JTP",D10="SE"),$X$13,IF(AND(C10="AY1",D10="SE"),$X$14,IF(AND(C10="T",D10="DS"),$X$15,IF(AND(C10="AS",D10="DS"),X$16,IF(AND(C10="AJ",D10="DS"),$X$17,IF(AND(C10="JTP",D10="DS"),$X$18,IF(AND(C10="AY1",D10="DS"),$X$19,IF(AND(C10="AY2",D10="DS"),$X$20,0)))))))))))))))) -> 88 | S10: =Q10/R10/G10 -> 2.84375 | T10: =SUM(Q7:Q10)/SUM(R7:R10)*H10 -> 5.5216963 | V10: T | W10: SE | X10: =Puntaje!S9 -> 88
G11: =SUM(G7:G10) -> 3.25 | I11: =SUM(I7:I10)/4 -> 0.75 | J11: =SUM(J7:J10)/4 -> 2.25 | K11: =SUM(K7:K10)/4 -> 2.5 | L11: =SUM(L7:L10)/4 -> 1.5 | M11: =SUM(M7:M10)/4 -> 2.25 | N11: =SUM(N7:N10)/4 -> 3 | O11: =SUM(O7:O10) -> 49 | P11: =AVERAGE(I11:N11) -> 2.0416667 | Q11: =SUM(Q7:Q10) -> 1399.75 | R11: =SUM(R7:R10) -> 312 | S11: =Q11/R11*H10 -> 5.5216963 | V11: AS | W11: SE | X11: =Puntaje!S10 -> 88
V12: AJ | W12: SE | X12: =Puntaje!S11 -> 48
V13: JTP | W13: SE | X13: =Puntaje!S12 -> 37
V14: AY1 | W14: SE | X14: =Puntaje!S13 -> 5
V15: T | W15: DS | X15: =Puntaje!S14 -> 88
V16: AS | W16: DS | X16: =Puntaje!S15 -> 88
V17: AJ | W17: DS | X17: =Puntaje!S16 -> 48
V18: JTP | W18: DS | X18: =Puntaje!S17 -> 37
V19: AY1 | W19: DS | X19: =Puntaje!S18 -> 5
V20: AY2 | W20: DS | X20: =Puntaje!S19 -> 0

Sheet AI1
B2: AI1: Categorización | F2: Cuadro 3.3.1.1: Ponderaciones según categorización | I2: Cuadro 3.3.1.2: Mínimos de PI1 según categoría docente
B3: Categoría | C3: ci | D3: ciw | F3: Categoría Investigación | G3: w | I3: Categoría | J3: Mínimo
B4: I | C4: 0 | D4: =IF(C4=1,G4,0) -> 0 | F4: I | G4: 10 | I4: T | J4: 3
B5: II | C5: 0 | D5: =IF(C5=1,G5,0) -> 0 | F5: II | G5: 5 | I5: AS | J5: 3
B6: III | C6: 0 | D6: =IF(C6=1,G6,0) -> 0 | F6: III | G6: 3 | I6: AJ | J6: 2
B7: IV | C7: 1 | D7: =IF(C7=1,G7,0) -> 2 | F7: IV | G7: 2 | I7: JTP | J7: 1
B8: V | C8: 0 | D8: =IF(C8=1,G8,0) -> 0 | F8: V | G8: 1 | I8: AY1 | J8: 0
I9: AY2 | J9: 0
C10: PI11 | D10: =SUM(D4:D8) -> 2
C11: AI11 | D11: =IF(AND(AI!$C$7="T",D10<$J$4),0,IF(AND(AI!$C$7="T",D10>$J$4),3,IF(AND(AI!$C$7="AS",D10<$J$5),0,IF(AND(AI!$C$7="AS",D10>$J$5),3,IF(AND(AI!$C$7="AJ",D10<$J$6),0,IF(AND(AI!$C$7="AJ",D10>$J$6),3,IF(AND(AI!$C$7="JTP",D10<$J$7),0,IF(AND(AI!$C$7="JTP",D10>$J$7),3,IF(AND(AI!$C$7="AY1",D10<$J$8),0,IF(AND(AI!$C$7="AY1",D10>$J$8),3,IF(AND(AI!$C$7="AY2",D10=0),0,IF(AND(AI!$C$7="AY2",D10>1),3,1)))))))))))) -> 1
I12: Cuadro 3.3.1.3: Valorización de AI1 según valor de PI1
B13: AI2: Categorización | I13: En relación al CIW | J13: AI1
B14: Categoría | C14: ci | D14: ciw | I14: Menor al mínimo | J14: 0
B15: I | C15: 0 | D15: =IF(C15=1,G4,0) -> 0 | I15: Igual al mínimo | J15: 1
B16: II | C16: 0 | D16: =IF(C16=1,G5,0) -> 0 | I16: Mayor al mínimo | J16: 3
B17: III | C17: 0 | D17: =IF(C17=1,G6,0) -> 0
B18: IV | C18: 1 | D18: =IF(C18=1,G7,0) -> 2
B19: V | C19: 0 | D19: =IF(C19=1,G8,0) -> 0
C21: PI12 | D21: =SUM(D15:D19) -> 2
C22: AI12 | D22: =IF(AND(AI!C8="T",D21<$J$4),0,IF(AND(AI!C8="T",D21>$J$4),3,IF(AND(AI!C8="AS",D21<$J$5),0,IF(AND(AI!C8="AS",D21>$J$5),3,IF(AND(AI!C8="AJ",D21<$J$6),0,IF(AND(AI!C8="AJ",D21>$J$6),3,IF(AND(AI!C8="JTP",D21<$J$7),0,IF(AND(AI!C8="JTP",D21>$J$7),3,IF(AND(AI!C8="AY1",D21<$J$8),0,IF(AND(AI!C8="AY1",D21>$J$8),3,IF(AND(AI!C8="AY2",D21=0),0,IF(AND(AI!C8="AY2",D21>1),3,1)))))))))))) -> 0
B24: AI3: Categorización
B25: Categoría | C25: ci | D25: ciw
B26: I | C26: 0 | D26: =IF(C26=1,G4,0) -> 0
B27: II | C27: 0 | D27: =IF(C27=1,G5,0) -> 0
B28: III | C28: 1 | D28: =IF(C28=1,G6,0) -> 3
B29: IV | C29: 0 | D29: =IF(C29=1,G7,0) -> 0
B30: V | C30: 0 | D30: =IF(C30=1,G8,0) -> 0
C32: PI13 | D32: =SUM(D26:D30) -> 3
C33: AI13 | D33: =IF(AND(AI!C9="T",D32<$J$4),0,IF(AND(AI!C9="T",D32>$J$4),3,IF(AND(AI!C9="AS",D32<$J$5),0,IF(AND(AI!C9="AS",D32>$J$5),3,IF(AND(AI!C9="AJ",D32<$J$6),0,IF(AND(AI!C9="AJ",D32>$J$6),3,IF(AND(AI!C9="JTP",D32<$J$7),0,IF(AND(AI!C9="JTP",D32>$J$7),3,IF(AND(AI!C9="AY1",D32<$J$8),0,IF(AND(AI!C9="AY1",D32>$J$8),3,IF(AND(AI!C9="AY2",D32=0),0,IF(AND(AI!C9="AY2",D32>1),3,1)))))))))))) -> 1
B35: AI4: Categorización
B36: Categoría | C36: ci | D36: ciw
B37: I | C37: 0 | D37: =IF(C37=1,G4,0) -> 0
B38: II | C38: 0 | D38: =IF(C38=1,G5,0) -> 0
B39: III | C39: 1 | D39: =IF(C39=1,G6,0) -> 3
B40: IV | C40: 0 | D40: =IF(C40=1,G7,0) -> 0
B41: V | C41: 0 | D41: =IF(C41=1,G8,0) -> 0
C43: PI14 | D43: =SUM(D37:D41) -> 3
C44: AI14 | D44: =IF(AND(AI!C10="T",D43<$J$4),0,IF(AND(AI!C10="T",D43>$J$4),3,IF(AND(AI!C10="AS",D43<$J$5),0,IF(AND(AI!C10="AS",D43>$J$5),3,IF(AND(AI!C10="AJ",D43<$J$6),0,IF(AND(AI!C10="AJ",D43>$J$6),3,IF(AND(AI!C10="JTP",D43<$J$7),0,IF(AND(AI!C10="JTP",D43>$J$7),3,IF(AND(AI!C10="AY1",D43<$J$8),0,IF(AND(AI!C10="AY1",D43>$J$8),3,IF(AND(AI!C10="AY2",D43=0),0,IF(AND(AI!C10="AY2",D43>1),3,1)))))))))))) -> 1

Sheet AI2
B2: AI2 Proyectos acreditados durante el periodo
B3: Año | C3: Proyecto de Investigación | K3: Participación en el proyecto | O3: Pryip | Q3: Cuadro 3.3.2.1: Valoración según tipo de proyecto | T3: Cuadro 3.3.2.2: Valoración según la característica del proyecto
C4: Título | D4: Organismo | E4: Tipo | F4: Tw | G4: Cáracter | H4: Período | I4: Código | J4: Prip | K4: Categoría | L4: hs/sem | M4: Pai | N4: fdip | Q4: Tipo | R4: Valor | T4: Carácter | U4: Valor
B5: 1 | C5: Muestreo | D5: UNCUYO | E5: I | F5: =IF(E5="I",$R$5,IF(E5="IV",$R$6,IF(E5="PICTO",$R$7,IF(E5="PICT",$R$8,0)))) -> 1 | G5: UNCUYO | H5: 2022-2024 | I5: A389 | J5: =IF(G5="UNCUYO",$U$5,IF(G5="Nacional",$U$6,IF(G5="Internacional",$U$7,0))) -> 1 | K5: I | L5: 4 | M5: =IF(K5="D",$R$13,IF(K5="Co",$R$14,IF(K5="I",$R$15,IF(K5="Cb",IF(K5="B",$R$17,0)*M5/40)))) -> 3 | N5: =L5/40 -> 0.1 | O5: =F5+J5+M5+N5 -> 5.1 | Q5: I | R5: 1 | T5: UNCUYO | U5: 1
B6: 1 | C6: Papas | D6: UNCUYO | E6: IV | F6: =IF(E6="I",$R$5,IF(E6="IV",$R$6,IF(E6="PICTO",$R$7,IF(E6="PICT",$R$8,0)))) -> 3 | G6: UNCUYO | H6: 2022-2024 | I6: A390 | J6: =IF(G6="UNCUYO",$U$5,IF(G6="Nacional",$U$6,IF(G6="Internacional",$U$7,0))) -> 1 | K6: Co | L6: 2 | M6: =IF(K6="D",$R$13,IF(K6="Co",$R$14,IF(K6="I",$R$15,IF(K6="Cb",IF(K6="B",$R$17,0)*M6/40)))) -> 5 | N6: =L6/40 -> 0.05 | O6: =F6+J6+M6+N6 -> 9.05 | Q6: IV | R6: 3 | T6: Nacional | U6: 3
B7: 1 | C7: Contaminación | D7: CONICET | E7: PICTO | F7: =IF(E7="I",$R$5,IF(E7="IV",$R$6,IF(E7="PICTO",$R$7,IF(E7="PICT",$R$8,0)))) -> 5 | G7: Nacional | H7: 2022-2024 | I7: A391 | J7: =IF(G7="UNCUYO",$U$5,IF(G7="Nacional",$U$6,IF(G7="Internacional",$U$7,0))) -> 3 | K7: I | L7: 2 | M7: =IF(K7="D",$R$13,IF(K7="Co",$R$14,IF(K7="I",$R$15,IF(K7="Cb",IF(K7="B",$R$17,0)*M7/40)))) -> 3 | N7: =L7/40 -> 0.05 | O7: =F7+J7+M7+N7 -> 11.05 | Q7: PICTO | R7: 5 | T7: Internacional | U7: 5
B8: 1 | C8: Sostenible | D8: UNCUYO | E8: PICT | F8: =IF(E8="I",$R$5,IF(E8="IV",$R$6,IF(E8="PICTO",$R$7,IF(E8="PICT",$R$8,0)))) -> 5 | G8: Internacional | H8: 2022-2024 | I8: A392 | J8: =IF(G8="UNCUYO",$U$5,IF(G8="Nacional",$U$6,IF(G8="Internacional",$U$7,0))) -> 5 | K8: I | L8: 2 | M8: =IF(K8="D",$R$13,IF(K8="Co",$R$14,IF(K8="I",$R$15,IF(K8="Cb",IF(K8="B",$R$17,0)*M8/40)))) -> 3 | N8: =L8/40 -> 0.05 | O8: =F8+J8+M8+N8 -> 13.05 | Q8: PICT | R8: 5
N10: PI21 | O10: =SUM(O5:O8) -> 38.25
N11: AI21 | O11: =IF(AND(AI!$C$7="T",O10<$U$13),0,IF(AND(AI!$C$7="T",O10>$U$13),3,IF(AND(AI!$C$7="AS",O10<$U$14),0,IF(AND(AI!$C$7="AS",O10>$U$14),3,IF(AND(AI!$C$7="AJ",O10<$U$15),0,IF(AND(AI!$C$7="AJ",O10>$U$15),3,IF(AND(AI!$C$7="JTP",O10<$U$16),0,IF(AND(AI!$C$7="JTP",O10>$U$16),3,IF(AND(AI!$C$7="AY1",O10<$U$17),0,IF(AND(AI!$C$7="AY1",O10>$U$17),3,IF(AND(AI!$C$7="AY2",O10=0),0,IF(AND(AI!$C$7="AY2",O10>1),3,1)))))))))))) -> 3 | Q11: Cuadro 3.3.2.3: Valoración según la participación al proyecto | T11: Cuadro 3.3.2.4: Mínimos de PI según categoría docente
Q12: Participación | R12: Valor | T12: Categoría | U12: Mínimo
Q13: D | R13: 10 | T13: T | U13: 9
B14: AI2 Proyectos acreditados durante el periodo | Q14: Co | R14: 5 | T14: AS | U14: 9
B15: Año | C15: Proyecto de Investigación | K15: Participación en el proyecto | O15: Pryi | Q15: I | R15: 3 | T15: AJ | U15: 5
C16: Título | D16: Organismo | E16: Tipo | F16: Tw | G16: Cáracter | H16: Período | I16: Código | J16: Pri | K16: Categoría | L16: hs/sem | M16: Pai | N16: fdi | Q16: Cb | R16: 1 | T16: JTP | U16: 5
B17: 2 | C17: Muestreo | D17: UNCUYO | E17: I | F17: =IF(E17="I",$R$5,IF(E17="IV",$R$6,IF(E17="PICTO",$R$7,IF(E17="PICT",$R$8,0)))) -> 1 | G17: UNCUYO | H17: 2022-2024 | I17: A389 | J17: =IF(G17="UNCUYO",$U$5,IF(G17="Nacional",$U$6,IF(G17="Internacional",$U$7,0))) -> 1 | K17: I | L17: 4 | M17: =IF(K17="D",$R$13,IF(K17="Co",$R$14,IF(K17="I",$R$15,IF(K17="Cb",IF(K17="B",$R$17,0)*M17/40)))) -> 3 | N17: =L17/40 -> 0.1 | O17: =F17+J17+M17+N17 -> 5.1 | Q17: B | R17: 1 | T17: AY1 | U17: 0
B18: 2 | C18: Muestreo | D18: UNCUYO | E18: I | F18: =IF(E18="I",$R$5,IF(E18="IV",$R$6,IF(E18="PICTO",$R$7,IF(E18="PICT",$R$8,0)))) -> 1 | G18: UNCUYO | H18: 2022-2025 | I18: A390 | J18: =IF(G18="UNCUYO",$U$5,IF(G18="Nacional",$U$6,IF(G18="Internacional",$U$7,0))) -> 1 | K18: I | L18: 2 | M18: =IF(K18="D",$R$13,IF(K18="Co",$R$14,IF(K18="I",$R$15,IF(K18="Cb",IF(K18="B",$R$17,0)*M18/40)))) -> 3 | N18: =L18/40 -> 0.05 | O18: =F18+J18+M18+N18 -> 5.05 | Q18: Ref: D: Director, Co: Codirector, I:Investigador, Cb:Colaborador, B:Becario | T18: AY2 | U18: 0
B19: 2 | F19: =IF(E19="I",$R$5,IF(E19="IV",$R$6,IF(E19="PICTO",$R$7,IF(E19="PICT",$R$8,0)))) -> 0 | J19: =IF(G19="UNCUYO",$U$5,IF(G19="Nacional",$U$6,IF(G19="Internacional",$U$7,0))) -> 0 | M19: =IF(K19="D",$R$13,IF(K19="Co",$R$14,IF(K19="I",$R$15,IF(K19="Cb",IF(K19="B",$R$17,0)*M19/40)))) -> FALSE | N19: =L19/40 -> 0 | O19: =F19+J19+M19+N19 -> 0
B20: 2 | F20: =IF(E20="I",$R$5,IF(E20="IV",$R$6,IF(E20="PICTO",$R$7,IF(E20="PICT",$R$8,0)))) -> 0 | J20: =IF(G20="UNCUYO",$U$5,IF(G20="Nacional",$U$6,IF(G20="Internacional",$U$7,0))) -> 0 | M20: =IF(K20="D",$R$13,IF(K20="Co",$R$14,IF(K20="I",$R$15,IF(K20="Cb",IF(K20="B",$R$17,0)*M20/40)))) -> FALSE | N20: =L20/40 -> 0 | O20: =F20+J20+M20+N20 -> 0 | Q20: Cuadro 3.3.2.5: Valorización de AI2 según valor de PI
Q21: En relación al PI | R21: AI2
N22: PI22 | O22: =SUM(O17:O20) -> 10.15 | Q22: Menor al mínimo | R22: 0
N23: AI22 | O23: =IF(AND(AI!$C$8="T",O22<$U$13),0,IF(AND(AI!$C$8="T",O22>$U$13),3,IF(AND(AI!$C$8="AS",O22<$U$14),0,IF(AND(AI!$C$8="AS",O22>$U$14),3,IF(AND(AI!$C$8="AJ",O22<$U$15),0,IF(AND(AI!$C$8="AJ",O22>$U$15),3,IF(AND(AI!$C$8="JTP",O22<$U$16),0,IF(AND(AI!$C$8="JTP",O22>$U$16),3,IF(AND(AI!$C$8="AY1",O22<$U$17),0,IF(AND(AI!$C$8="AY1",O22>$U$17),3,IF(AND(AI!$C$8="AY2",O22=0),0,IF(AND(AI!$C$8="AY2",O22>1),3,1)))))))))))) -> 3 | Q23: Igual al mínimo | R23: 1
Q24: Mayor al mínimo | R24: 3
B25: AI2 Proyectos acreditados durante el periodo
B26: Año | C26: Proyecto de Investigación | K26: Participación en el proyecto | O26: Pryi
C27: Título | D27: Organismo | E27: Tipo | F27: Tw | G27: Cáracter | H27: Período | I27: Código | J27: Pri | K27: Categoría | L27: hs/sem | M27: Pai | N27: fdi
B28: 3 | C28: Muestreo | D28: UNCUYO | E28: I | F28: =IF(E28="I",$R$5,IF(E28="IV",$R$6,IF(E28="PICTO",$R$7,IF(E28="PICT",$R$8,0)))) -> 1 | G28: UNCUYO | H28: 2022-2024 | I28: A389 | J28: =IF(G28="UNCUYO",$U$5,IF(G28="Nacional",$U$6,IF(G28="Internacional",$U$7,0))) -> 1 | K28: I | L28: 4 | M28: =IF(K28="D",$R$13,IF(K28="Co",$R$14,IF(K28="I",$R$15,IF(K28="Cb",IF(K28="B",$R$17,0)*M28/40)))) -> 3 | N28: =L28/40 -> 0.1 | O28: =F28+J28+M28+N28 -> 5.1
B29: 3 | F29: =IF(E29="I",$R$5,IF(E29="IV",$R$6,IF(E29="PICTO",$R$7,IF(E29="PICT",$R$8,0)))) -> 0 | J29: =IF(G29="UNCUYO",$U$5,IF(G29="Nacional",$U$6,IF(G29="Internacional",$U$7,0))) -> 0 | M29: =IF(K29="D",$R$13,IF(K29="Co",$R$14,IF(K29="I",$R$15,IF(K29="Cb",IF(K29="B",$R$17,0)*M29/40)))) -> FALSE | N29: =L29/40 -> 0 | O29: =F29+J29+M29+N29 -> 0
B30: 3 | F30: =IF(E30="I",$R$5,IF(E30="IV",$R$6,IF(E30="PICTO",$R$7,IF(E30="PICT",$R$8,0)))) -> 0 | J30: =IF(G30="UNCUYO",$U$5,IF(G30="Nacional",$U$6,IF(G30="Internacional",$U$7,0))) -> 0 | M30: =IF(K30="D",$R$13,IF(K30="Co",$R$14,IF(K30="I",$R$15,IF(K30="Cb",IF(K30="B",$R$17,0)*M30/40)))) -> FALSE | N30: =L30/40 -> 0 | O30: =F30+J30+M30+N30 -> 0
B31: 3 | F31: =IF(E31="I",$R$5,IF(E31="IV",$R$6,IF(E31="PICTO",$R$7,IF(E31="PICT",$R$8,0)))) -> 0 | J31: =IF(G31="UNCUYO",$U$5,IF(G31="Nacional",$U$6,IF(G31="Internacional",$U$7,0))) -> 0 | M31: =IF(K31="D",$R$13,IF(K31="Co",$R$14,IF(K31="I",$R$15,IF(K31="Cb",IF(K31="B",$R$17,0)*M31/40)))) -> FALSE | N31: =L31/40 -> 0 | O31: =F31+J31+M31+N31 -> 0
N33: PI23 | O33: =SUM(O28:O31) -> 5.1
N34: AI23 | O34: =IF(AND(AI!$C$9="T",O33<$U$13),0,IF(AND(AI!$C$9="T",O33>$U$13),3,IF(AND(AI!$C$9="AS",O33<$U$14),0,IF(AND(AI!$C$9="AS",O33>$U$14),3,IF(AND(AI!$C$9="AJ",O33<$U$15),0,IF(AND(AI!$C$9="AJ",O33>$U$15),3,IF(AND(AI!$C$9="JTP",O33<$U$16),0,IF(AND(AI!$C$9="JTP",O33>$U$16),3,IF(AND(AI!$C$9="AY1",O33<$U$17),0,IF(AND(AI!$C$9="AY1",O33>$U$17),3,IF(AND(AI!$C$9="AY2",O33=0),0,IF(AND(AI!$C$9="AY2",O33>1),3,1)))))))))))) -> 0
B36: AI2 Proyectos acreditados durante el periodo
B37: Año | C37: Proyecto de Investigación | K37: Participación en el proyecto | O37: Pryi
C38: Nombre | D38: Organismo | E38: Tipo | F38: Tw | G38: Cáracter | H38: Período | I38: Código | J38: Pri | K38: Categoría | L38: hs/sem | M38: Pai | N38: fdi
B39: 4 | C39: Muestreo | D39: UNCUYO | E39: I | F39: =IF(E39="I",$R$5,IF(E39="IV",$R$6,IF(E39="PICTO",$R$7,IF(E39="PICT",$R$8,0)))) -> 1 | G39: UNCUYO | H39: 2022-2024 | I39: A389 | J39: =IF(G39="UNCUYO",$U$5,IF(G39="Nacional",$U$6,IF(G39="Internacional",$U$7,0))) -> 1 | K39: I | L39: 4 | M39: =IF(K39="D",$R$13,IF(K39="Co",$R$14,IF(K39="I",$R$15,IF(K39="Cb",IF(K39="B",$R$17,0)*M39/40)))) -> 3 | N39: =L39/40 -> 0.1 | O39: =F39+J39+M39+N39 -> 5.1
B40: 4 | C40: Papas | D40: UNCUYO | E40: IV | F40: =IF(E40="I",$R$5,IF(E40="IV",$R$6,IF(E40="PICTO",$R$7,IF(E40="PICT",$R$8,0)))) -> 3 | G40: UNCUYO | H40: 2022-2024 | I40: A390 | J40: =IF(G40="UNCUYO",$U$5,IF(G40="Nacional",$U$6,IF(G40="Internacional",$U$7,0))) -> 1 | K40: Co | L40: 2 | M40: =IF(K40="D",$R$13,IF(K40="Co",$R$14,IF(K40="I",$R$15,IF(K40="Cb",IF(K40="B",$R$17,0)*M40/40)))) -> 5 | N40: =L40/40 -> 0.05 | O40: =F40+J40+M40+N40 -> 9.05
B41: 4 | C41: Contaminación | D41: CONICET | E41: PICTO | F41: =IF(E41="I",$R$5,IF(E41="IV",$R$6,IF(E41="PICTO",$R$7,IF(E41="PICT",$R$8,0)))) -> 5 | G41: Nacional | H41: 2022-2024 | I41: A391 | J41: =IF(G41="UNCUYO",$U$5,IF(G41="Nacional",$U$6,IF(G41="Internacional",$U$7,0))) -> 3 | K41: I | L41: 2 | M41: =IF(K41="D",$R$13,IF(K41="Co",$R$14,IF(K41="I",$R$15,IF(K41="Cb",IF(K41="B",$R$17,0)*M41/40)))) -> 3 | N41: =L41/40 -> 0.05 | O41: =F41+J41+M41+N41 -> 11.05
B42: 4 | C42: Sostenible | D42: UNCUYO | E42: PICT | F42: =IF(E42="I",$R$5,IF(E42="IV",$R$6,IF(E42="PICTO",$R$7,IF(E42="PICT",$R$8,0)))) -> 5 | G42: Internacional | H42: 2022-2024 | I42: A392 | J42: =IF(G42="UNCUYO",$U$5,IF(G42="Nacional",$U$6,IF(G42="Internacional",$U$7,0))) -> 5 | K42: I | L42: 2 | M42: =IF(K42="D",$R$13,IF(K42="Co",$R$14,IF(K42="I",$R$15,IF(K42="Cb",IF(K42="B",$R$17,0)*M42/40)))) -> 3 | N42: =L42/40 -> 0.05 | O42: =F42+J42+M42+N42 -> 13.05
N44: PI24 | O44: =SUM(O39:O42) -> 38.25
N45: AI24 | O45: =IF(AND(AI!$C$10="T",O44<$U$13),0,IF(AND(AI!$C$10="T",O44>$U$13),3,IF(AND(AI!$C$10="AS",O44<$U$14),0,IF(AND(AI!$C$10="AS",O44>$U$14),3,IF(AND(AI!$C$10="AJ",O44<$U$15),0,IF(AND(AI!$C$10="AJ",O44>$U$15),3,IF(AND(AI!$C$10="JTP",O44<$U$16),0,IF(AND(AI!$C$10="JTP",O44>$U$16),3,IF(AND(AI!$C$10="AY1",O44<$U$17),0,IF(AND(AI!$C$10="AY1",O44>$U$17),3,IF(AND(AI!$C$10="AY2",O44=0),0,IF(AND(AI!$C$10="AY2",O44>1),3,1)))))))))))) -> 3

Sheet AI3
B2: AI3 : Formación de recursos humanos en investigación | I2: Cuadro 3.3.3.1: Valoración según categoría | L2: Cuadro 3.3.3.3: Mínimos de PI3 según categoría docente
B3: Año | C3: Categoría | D3: Vcip | E3: Rol docente | F3: Rdip | G3: PI3p | I3: Categoría | J3: Valoración | L3: Categoría | M3: Mínimo
B4: 1 | C4: Investigador | D4: =IF(C4="Investigador",$J$4,IF(C4="Pasante",$J$5,IF(C4="Concurrente",$J$6,IF(C4="Tesista de posgrado",$J$7,0)))) -> 10 | E4: Director | F4: =IF(E4="Director",$J$11,IF(E4="Codirector",$J$12,IF(E4="Evaluador",$J$13,0))) -> 10 | G4: =D4+F4 -> 20 | I4: Investigador | J4: 10 | L4: T | M4: 30
B5: 1 | C5: Investigador | D5: =IF(C5="Investigador",$J$4,IF(C5="Pasante",$J$5,IF(C5="Concurrente",$J$6,IF(C5="Tesista de posgrado",$J$7,0)))) -> 10 | E5: Director | F5: =IF(E5="Director",$J$11,IF(E5="Codirector",$J$12,IF(E5="Evaluador",$J$13,0))) -> 10 | G5: =D5+F5 -> 20 | I5: Pasante | J5: 5 | L5: AS | M5: 30
B6: 1 | C6: Investigador | D6: =IF(C6="Investigador",$J$4,IF(C6="Pasante",$J$5,IF(C6="Concurrente",$J$6,IF(C6="Tesista de posgrado",$J$7,0)))) -> 10 | E6: Director | F6: =IF(E6="Director",$J$11,IF(E6="Codirector",$J$12,IF(E6="Evaluador",$J$13,0))) -> 10 | G6: =D6+F6 -> 20 | I6: Concurrente | J6: 3 | L6: AJ | M6: 20
B7: 1 | C7: Tesista de posgrado | D7: =IF(C7="Investigador",$J$4,IF(C7="Pasante",$J$5,IF(C7="Concurrente",$J$6,IF(C7="Tesista de posgrado",$J$7,0)))) -> 10 | E7: Evaluador | F7: =IF(E7="Director",$J$11,IF(E7="Codirector",$J$12,IF(E7="Evaluador",$J$13,0))) -> 10 | G7: =D7+F7 -> 20 | I7: Tesista de Posgrado | J7: 10 | L7: JTP | M7: 0
L8: AY1 | M8: 0
F9: PI31 | G9: =SUM(G4:G7) -> 80 | I9: Cuadro 3.3.3.2: Valoración según el rol del docente | L9: AY2 | M9: 0
F10: AI31 | G10: =IF(AND(AI!$C$7="T",G9<$M$4),0,IF(AND(AI!$C$7="T",G9>$M$4),3,IF(AND(AI!$C$7="AS",G9<$M$5),0,IF(AND(AI!$C$7="AS",G9>$M$5),3,IF(AND(AI!$C$7="AJ",G9<$M$6),0,IF(AND(AI!$C$7="AJ",G9>$M$6),3,IF(AND(AI!$C$7="JTP",G9<$M$7),0,IF(AND(AI!$C$7="JTP",G9>$M$7),3,IF(AND(AI!$C$7="AY1",G9<$M$8),0,IF(AND(AI!$C$7="AY1",G9>$M$8),3,IF(AND(AI!$C$7="AY2",G9=0),0,IF(AND(AI!$C$7="AY2",G9>1),3,1)))))))))))) -> 3 | I10: Rol | J10: Valoración
I11: Director | J11: 10 | L11: Cuadro 3.3.3.4: Valorización de AI3 según valor de PI3
B12: Año | C12: Categoría | D12: Vcip | E12: Rol docente | F12: Rdip | G12: PI3p | I12: Codirector | J12: 5 | L12: En relación al Imp | M12: AI3
B13: 2 | C13: Investigador | D13: =IF(C13="Investigador",$J$4,IF(C13="Pasante",$J$5,IF(C13="Concurrente",$J$6,IF(C13="Tesista de posgrado",$J$7,0)))) -> 10 | E13: Director | F13: =IF(E13="Director",$J$11,IF(E13="Codirector",$J$12,IF(E13="Evaluador",$J$13,0))) -> 10 | G13: =D13+F13 -> 20 | I13: Evaluador | J13: 10 | L13: Menor al mínimo | M13: 0
B14: 2 | D14: =IF(C14="Investigador",$J$4,IF(C14="Pasante",$J$5,IF(C14="Concurrente",$J$6,IF(C14="Tesista de posgrado",$J$7,0)))) -> 0 | F14: =IF(E14="Director",$J$11,IF(E14="Codirector",$J$12,IF(E14="Evaluador",$J$13,0))) -> 0 | G14: =D14+F14 -> 0 | L14: Igual al mínimo | M14: 1
B15: 2 | D15: =IF(C15="Investigador",$J$4,IF(C15="Pasante",$J$5,IF(C15="Concurrente",$J$6,IF(C15="Tesista de posgrado",$J$7,0)))) -> 0 | F15: =IF(E15="Director",$J$11,IF(E15="Codirector",$J$12,IF(E15="Evaluador",$J$13,0))) -> 0 | G15: =D15+F15 -> 0 | L15: Mayor al mínimo | M15: 3
B16: 2 | D16: =IF(C16="Investigador",$J$4,IF(C16="Pasante",$J$5,IF(C16="Concurrente",$J$6,IF(C16="Tesista de posgrado",$J$7,0)))) -> 0 | F16: =IF(E16="Director",$J$11,IF(E16="Codirector",$J$12,IF(E16="Evaluador",$J$13,0))) -> 0 | G16: =D16+F16 -> 0
F18: PI32 | G18: =SUM(G13:G16) -> 20
F19: AI32 | G19: =IF(AND(AI!$C$7="T",G18<$M$4),0,IF(AND(AI!$C$7="T",G18>$M$4),3,IF(AND(AI!$C$7="AS",G18<$M$5),0,IF(AND(AI!$C$7="AS",G18>$M$5),3,IF(AND(AI!$C$7="AJ",G18<$M$6),0,IF(AND(AI!$C$7="AJ",G18>$M$6),3,IF(AND(AI!$C$7="JTP",G18<$M$7),0,IF(AND(AI!$C$7="JTP",G18>$M$7),3,IF(AND(AI!$C$7="AY1",G18<$M$8),0,IF(AND(AI!$C$7="AY1",G18>$M$8),3,IF(AND(AI!$C$7="AY2",G18=0),0,IF(AND(AI!$C$7="AY2",G18>1),3,1)))))))))))) -> 1
B21: Año | C21: Categoría | D21: Vcip | E21: Rol docente | F21: Rdip | G21: PI3p
B22: 3 | C22: Investigador | D22: =IF(C22="Investigador",$J$4,IF(C22="Pasante",$J$5,IF(C22="Concurrente",$J$6,IF(C22="Tesista de posgrado",$J$7,0)))) -> 10 | E22: Director | F22: =IF(E22="Director",$J$11,IF(E22="Codirector",$J$12,IF(E22="Evaluador",$J$13,0))) -> 10 | G22: =D22+F22 -> 20
B23: 3 | D23: =IF(C23="Investigador",$J$4,IF(C23="Pasante",$J$5,IF(C23="Concurrente",$J$6,IF(C23="Tesista de posgrado",$J$7,0)))) -> 0 | E23: Director | F23: =IF(E23="Director",$J$11,IF(E23="Codirector",$J$12,IF(E23="Evaluador",$J$13,0))) -> 10 | G23: =D23+F23 -> 10
B24: 3 | D24: =IF(C24="Investigador",$J$4,IF(C24="Pasante",$J$5,IF(C24="Concurrente",$J$6,IF(C24="Tesista de posgrado",$J$7,0)))) -> 0 | E24: Director | F24: =IF(E24="Director",$J$11,IF(E24="Codirector",$J$12,IF(E24="Evaluador",$J$13,0))) -> 10 | G24: =D24+F24 -> 10
B25: 3 | C25: Tesista de posgrado | D25: =IF(C25="Investigador",$J$4,IF(C25="Pasante",$J$5,IF(C25="Concurrente",$J$6,IF(C25="Tesista de posgrado",$J$7,0)))) -> 10 | E25: Evaluador | F25: =IF(E25="Director",$J$11,IF(E25="Codirector",$J$12,IF(E25="Evaluador",$J$13,0))) -> 10 | G25: =D25+F25 -> 20
F27: PI33 | G27: =SUM(G22:G25) -> 60
F28: AI33 | G28: =IF(AND(AI!$C$7="T",G27<$M$4),0,IF(AND(AI!$C$7="T",G27>$M$4),3,IF(AND(AI!$C$7="AS",G27<$M$5),0,IF(AND(AI!$C$7="AS",G27>$M$5),3,IF(AND(AI!$C$7="AJ",G27<$M$6),0,IF(AND(AI!$C$7="AJ",G27>$M$6),3,IF(AND(AI!$C$7="JTP",G27<$M$7),0,IF(AND(AI!$C$7="JTP",G27>$M$7),3,IF(AND(AI!$C$7="AY1",G27<$M$8),0,IF(AND(AI!$C$7="AY1",G27>$M$8),3,IF(AND(AI!$C$7="AY2",G27=0),0,IF(AND(AI!$C$7="AY2",G27>1),3,1)))))))))))) -> 3
B30: Año | C30: Categoría | D30: Vcip | E30: Rol docente | F30: Rdip | G30: PI3p
B31: 4 | C31: Investigador | D31: =IF(C31="Investigador",$J$4,IF(C31="Pasante",$J$5,IF(C31="Concurrente",$J$6,IF(C31="Tesista de posgrado",$J$7,0)))) -> 10 | E31: Director | F31: =IF(E31="Director",$J$11,IF(E31="Codirector",$J$12,IF(E31="Evaluador",$J$13,0))) -> 10 | G31: =D31+F31 -> 20
B32: 4 | C32: Investigador | D32: =IF(C32="Investigador",$J$4,IF(C32="Pasante",$J$5,IF(C32="Concurrente",$J$6,IF(C32="Tesista de posgrado",$J$7,0)))) -> 10 | E32: Director | F32: =IF(E32="Director",$J$11,IF(E32="Codirector",$J$12,IF(E32="Evaluador",$J$13,0))) -> 10 | G32: =D32+F32 -> 20
B33: 4 | C33: Investigador | D33: =IF(C33="Investigador",$J$4,IF(C33="Pasante",$J$5,IF(C33="Concurrente",$J$6,IF(C33="Tesista de posgrado",$J$7,0)))) -> 10 | E33: Director | F33: =IF(E33="Director",$J$11,IF(E33="Codirector",$J$12,IF(E33="Evaluador",$J$13,0))) -> 10 | G33: =D33+F33 -> 20
B34: 4 | C34: Tesista de posgrado | D34: =IF(C34="Investigador",$J$4,IF(C34="Pasante",$J$5,IF(C34="Concurrente",$J$6,IF(C34="Tesista de posgrado",$J$7,0)))) -> 10 | E34: Evaluador | F34: =IF(E34="Director",$J$11,IF(E34="Codirector",$J$12,IF(E34="Evaluador",$J$13,0))) -> 10 | G34: =D34+F34 -> 20
F36: PI34 | G36: =SUM(G31:G34) -> 80
F37: AI34 | G37: =IF(AND(AI!$C$7="T",G36<$M$4),0,IF(AND(AI!$C$7="T",G36>$M$4),3,IF(AND(AI!$C$7="AS",G36<$M$5),0,IF(AND(AI!$C$7="AS",G36>$M$5),3,IF(AND(AI!$C$7="AJ",G36<$M$6),0,IF(AND(AI!$C$7="AJ",G36>$M$6),3,IF(AND(AI!$C$7="JTP",G36<$M$7),0,IF(AND(AI!$C$7="JTP",G36>$M$7),3,IF(AND(AI!$C$7="AY1",G36<$M$8),0,IF(AND(AI!$C$7="AY1",G36>$M$8),3,IF(AND(AI!$C$7="AY2",G36=0),0,IF(AND(AI!$C$7="AY2",G36>1),3,1)))))))))))) -> 3

Sheet AI4
B2: AI4 : Publicaciones en revistas científicas, de divulgación científicas o libros, registros y patentes
B3: Año | C3: Revistas científicas | O3: Revista de divulgación científca | T3: Libros | AD3: Cuadro 3.3.4.1: Valoración según cuartil de revista indexada
C4: Título del artículo | D4: Autores | E4: Nombre de la | G4: Indexadas | L4: No indexadas | O4: Título del | P4: Autores | Q4: Nombre de la | R4: Referencia | T4: Título del | U4: Completo | V4: Capítulo | X4: Autores | Y4: Indexado | Z4: No indexado | AD4: Categoría | AE4: Mínimo
E5: Revista | F5: Referencia | G5: Q1 | H5: Q2 | I5: Q3 | J5: Q4 | K5: IH | L5: Referato | M5: Sin Referato | N5: Prci | O5: Artículo | Q5: Revista | S5: Prdi | T5: Libro | W5: Título | Y5: Referencia | AA5: Pli | AB5: pbi | AD5: Q1 | AE5: 30
B6: 1 | C6: Sumo nnn | D6: Pepe- Juan | E6: Rev Fac Cienc Agrarias | F6: Vol 2 | G6: 0 | H6: 1 | I6: 0 | J6: 0 | K6: 14 | L6: 1 | M6: 0 | N6: =G6*$AE$5+H6*$AE$6+I6*$AE$7+J6*$AE$8+K6 -> 34 | O6: 0 | P6: 0 | Q6: 0 | R6: 0 | S6: =IF(O6=0,0,10) -> 0 | T6: 0 | U6: 0 | V6: 0 | X6: 0 | Y6: 0 | Z6: 0 | AA6: =U6*$AE$13+V6*$AE$14 -> 0 | AB6: =AA6+S6+N6 -> 34 | AD6: Q2 | AE6: 20
B7: 1 | C7: 0 | D7: 0 | E7: 0 | F7: 0 | G7: 0 | H7: 0 | I7: 0 | J7: 0 | K7: 0 | L7: 0 | M7: 0 | N7: =G7*$AE$5+H7*$AE$6+I7*$AE$7+J7*$AE$8+K7 -> 0 | O7: El suelo fértil | P7: Adrián | Q7: Experticia | R7: Vol3-pg 23-24 | S7: =IF(O7=0,0,10) -> 10 | T7: 0 | U7: 0 | V7: 0 | X7: 0 | Y7: 0 | Z7: 0 | AA7: =U7*$AE$13+V7*$AE$14 -> 0 | AB7: =AA7+S7+N7 -> 10 | AD7: Q3 | AE7: 10
B8: 1 | C8: 0 | D8: 0 | E8: 0 | F8: 0 | G8: 0 | H8: 0 | I8: 0 | J8: 0 | K8: 0 | L8: 0 | M8: 0 | N8: =G8*$AE$5+H8*$AE$6+I8*$AE$7+J8*$AE$8+K8 -> 0 | O8: 0 | P8: 0 | Q8: 0 | R8: 0 | S8: =IF(O8=0,0,10) -> 0 | T8: Reforastación | U8: 0 | V8: 1 | W8: Algarrobo | X8: Pepe | Y8: 1 | Z8: 0 | AA8: =U8*$AE$13+V8*$AE$14 -> 20 | AB8: =AA8+S8+N8 -> 20 | AD8: Q4 | AE8: 5
B9: 1 | C9: 0 | D9: 0 | E9: 0 | F9: 0 | G9: 0 | H9: 0 | I9: 0 | J9: 0 | K9: 0 | L9: 0 | M9: 0 | N9: =G9*$AE$5+H9*$AE$6+I9*$AE$7+J9*$AE$8+K9 -> 0 | O9: 0 | P9: 0 | Q9: 0 | R9: 0 | S9: =IF(O9=0,0,10) -> 0 | T9: 0 | U9: 0 | V9: 0 | W9: 0 | X9: 0 | Y9: 0 | Z9: 0 | AA9: =U9*$AE$13+V9*$AE$14 -> 0 | AB9: =AA9+S9+N9 -> 0
B10: 1 | C10: 0 | D10: 0 | E10: 0 | F10: 0 | G10: 0 | H10: 0 | I10: 0 | J10: 0 | K10: 0 | L10: 0 | M10: 0 | N10: =G10*$AE$5+H10*$AE$6+I10*$AE$7+J10*$AE$8+K10 -> 0 | O10: 0 | P10: 0 | Q10: 0 | R10: 0 | S10: =IF(O10=0,0,10) -> 0 | T10: 0 | U10: 0 | V10: 0 | W10: 0 | X10: 0 | Y10: 0 | Z10: 0 | AA10: =U10*$AE$13+V10*$AE$14 -> 0 | AB10: =AA10+S10+N10 -> 0
AD11: Cuadro 3.3.4.2: Valoración según publicación de libros
AA12: PI41 | AB12: =SUM(AB6:AB8) -> 64 | AD12: Libro | AE12: Valoración
AA13: AI41 | AB13: =IF(AND(AI!$C$7="T",AB12<$AE$19),0,IF(AND(AI!$C$7="T",AB12>$AE$19),3,IF(AND(AI!$C$7="AS",AB12<$AE$20),0,IF(AND(AI!$C$7="AS",AB12>$AE$20),3,IF(AND(AI!$C$7="AJ",AB12<$AE$19),0,IF(AND(AI!$C$7="AJ",AB12>$AE$19),3,IF(AND(AI!$C$7="JTP",AB12<$AE$21),0,IF(AND(AI!$C$7="JTP",AB12>$AE$21),3,IF(AND(AI!$C$7="AY1",AB12<$AE$22),0,IF(AND(AI!$C$7="AY1",AB12>$AE$22),3,IF(AND(AI!$C$7="AY2",AB12=0),0,IF(AND(AI!$C$7="AY2",AB12>1),3,1)))))))))))) -> 3 | AD13: Completo | AE13: 50
AD14: Capítulo | AE14: 20
B15: Año | C15: Revistas científicas | O15: Revista de divulgación científca | T15: Libros
C16: Título del artículo | D16: Autores | E16: Nombre de la | G16: Indexadas | L16: No indexadas | O16: Título del | P16: Autores | Q16: Nombre de la | R16: Referencia | T16: Título del | U16: Completo | V16: Capítulo | X16: Autores | Y16: Indexado | Z16: No indexado
E17: Revista | F17: Referencia | G17: Q1 | H17: Q2 | I17: Q3 | J17: Q4 | K17: IH | L17: Referato | M17: Sin Referato | N17: Prci | O17: Artículo | Q17: Revista | S17: Prdi | T17: Libro | W17: Título | Y17: Referencia | AA17: Pli | AB17: pbi | AD17: Cuadro 3.3.4.3: Mínimos de PI4 según categoría docente
B18: 2 | C18: 0 | D18: 0 | E18: 0 | F18: 0 | G18: 0 | H18: 0 | I18: 0 | J18: 0 | K18: 0 | L18: 1 | M18: 0 | N18: =G18*$AE$5+H18*$AE$6+I18*$AE$7+J18*$AE$8+K18 -> 0 | O18: 0 | P18: 0 | Q18: 0 | R18: 0 | S18: =IF(O18=0,0,10) -> 0 | T18: 0 | U18: 0 | V18: 0 | W18: 0 | X18: 0 | Y18: 0 | Z18: 0 | AA18: =U18*$AE$13+V18*$AE$14 -> 0 | AB18: =AA18+S18+N18 -> 0 | AD18: Categoría | AE18: Mínimo
B19: 2 | C19: 0 | D19: 0 | E19: 0 | F19: 0 | G19: 0 | H19: 0 | I19: 0 | J19: 0 | K19: 0 | L19: 0 | M19: 0 | N19: =G19*$AE$5+H19*$AE$6+I19*$AE$7+J19*$AE$8+K19 -> 0 | O19: El Jardín | P19: Adrián | Q19: Experticia | R19: Vol2-pg 3-8 | S19: =IF(O19=0,0,10) -> 10 | T19: 0 | U19: 0 | V19: 0 | W19: 0 | X19: 0 | Y19: 0 | Z19: 0 | AA19: =U19*$AE$13+V19*$AE$14 -> 0 | AB19: =AA19+S19+N19 -> 10 | AD19: T | AE19: 20
B20: 2 | C20: 0 | D20: 0 | E20: 0 | F20: 0 | G20: 0 | H20: 0 | I20: 0 | J20: 0 | K20: 0 | L20: 0 | M20: 0 | N20: =G20*$AE$5+H20*$AE$6+I20*$AE$7+J20*$AE$8+K20 -> 0 | O20: 0 | P20: 0 | Q20: 0 | R20: 0 | S20: =IF(O20=0,0,10) -> 0 | T20: 0 | U20: 0 | V20: 0 | W20: 0 | X20: 0 | Y20: , | Z20: 0 | AA20: =U20*$AE$13+V20*$AE$14 -> 0 | AB20: =AA20+S20+N20 -> 0 | AD20: AS | AE20: 20
B21: 2 | C21: 0 | D21: 0 | E21: 0 | F21: 0 | G21: 0 | H21: 0 | I21: 0 | J21: 0 | K21: 0 | L21: 0 | M21: 0 | N21: =G21*$AE$5+H21*$AE$6+I21*$AE$7+J21*$AE$8+K21 -> 0 | O21: 0 | P21: 0 | Q21: 0 | R21: 0 | S21: =IF(O21=0,0,10) -> 0 | T21: 0 | U21: 0 | V21: 0 | W21: 0 | X21: 0 | Y21: 0 | Z21: 0 | AA21: =U21*$AE$13+V21*$AE$14 -> 0 | AB21: =AA21+S21+N21 -> 0 | AD21: AJ | AE21: 10
B22: 2 | C22: 0 | D22: 0 | E22: 0 | F22: 0 | G22: 0 | H22: 0 | I22: 0 | J22: 0 | K22: 0 | L22: 0 | M22: 0 | N22: =G22*$AE$5+H22*$AE$6+I22*$AE$7+J22*$AE$8+K22 -> 0 | O22: 0 | P22: 0 | Q22: 0 | R22: 0 | S22: =IF(O22=0,0,10) -> 0 | T22: 0 | U22: 0 | V22: 0 | W22: 0 | X22: 0 | Y22: 0 | Z22: 0 | AA22: =U22*$AE$13+V22*$AE$14 -> 0 | AB22: =AA22+S22+N22 -> 0 | AD22: JTP | AE22: 5
AD23: AY1 | AE23: 0
AA24: PI42 | AB24: =SUM(AB18:AB20) -> 10 | AD24: AY2 | AE24: 0
AA25: AI42 | AB25: =IF(AND(AI!$C$7="T",AB24<$AE$19),0,IF(AND(AI!$C$7="T",AB24>$AE$19),3,IF(AND(AI!$C$7="AS",AB24<$AE$20),0,IF(AND(AI!$C$7="AS",AB24>$AE$20),3,IF(AND(AI!$C$7="AJ",AB24<$AE$19),0,IF(AND(AI!$C$7="AJ",AB24>$AE$19),3,IF(AND(AI!$C$7="JTP",AB24<$AE$21),0,IF(AND(AI!$C$7="JTP",AB24>$AE$21),3,IF(AND(AI!$C$7="AY1",AB24<$AE$22),0,IF(AND(AI!$C$7="AY1",AB24>$AE$22),3,IF(AND(AI!$C$7="AY2",AB24=0),0,IF(AND(AI!$C$7="AY2",AB24>1),3,1)))))))))))) -> 0
AD26: Cuadro 3.3.4.4: Valorización de AI4 según valor de PI4
AD27: En relación al PI4 | AE27: AI4
B28: Año | C28: Revistas científicas | O28: Revista de divulgación científca | T28: Libros | AD28: Menor al mínimo | AE28: 0
C29: Título del artículo | D29: Autores | E29: Nombre de la | G29: Indexadas | L29: No indexadas | O29: Título del | P29: Autores | Q29: Nombre de la | R29: Referencia | T29: Título del | U29: Completo | V29: Capítulo | X29: Autores | Y29: Indexado | Z29: No indexado | AD29: Igual al mínimo | AE29: 1
E30: Revista | F30: Referencia | G30: Q1 | H30: Q2 | I30: Q3 | J30: Q4 | K30: IH | L30: Referato | M30: Sin Referato | N30: Prci | O30: Artículo | Q30: Revista | S30: Prdi | T30: Libro | W30: Título | Y30: Referencia | AA30: Pli | AB30: pbi | AD30: Mayor al mínimo | AE30: 3
B31: 3 | C31: 0 | D31: 0 | E31: 0 | F31: 0 | G31: 0 | H31: 0 | I31: 0 | J31: 0 | K31: 0 | L31: 0 | M31: 0 | N31: =G31*$AE$5+H31*$AE$6+I31*$AE$7+J31*$AE$8+K31 -> 0 | O31: 0 | P31: 0 | Q31: 0 | R31: 0 | S31: =IF(O31=0,0,10) -> 0 | T31: 0 | U31: 0 | V31: 0 | W31: 0 | X31: 0 | Y31: 0 | Z31: 0 | AA31: =U31*$AE$13+V31*$AE$14 -> 0 | AB31: =AA31+S31+N31 -> 0
B32: 3 | C32: 0 | D32: 0 | E32: 0 | F32: 0 | G32: 0 | H32: 0 | I32: 0 | J32: 0 | K32: 0 | L32: 0 | M32: 0 | N32: =G32*$AE$5+H32*$AE$6+I32*$AE$7+J32*$AE$8+K32 -> 0 | O32: 0 | P32: 0 | Q32: 0 | R32: 0 | S32: =IF(O32=0,0,10) -> 0 | T32: 0 | U32: 0 | V32: 0 | W32: 0 | X32: 0 | Y32: 0 | Z32: 0 | AA32: =U32*$AE$13+V32*$AE$14 -> 0 | AB32: =AA32+S32+N32 -> 0
B33: 3 | C33: 0 | D33: 0 | E33: 0 | F33: 0 | G33: 0 | H33: 0 | I33: 0 | J33: 0 | K33: 0 | L33: 0 | M33: 0 | N33: =G33*$AE$5+H33*$AE$6+I33*$AE$7+J33*$AE$8+K33 -> 0 | O33: 0 | P33: 0 | Q33: 0 | R33: 0 | S33: =IF(O33=0,0,10) -> 0 | T33: 0 | U33: 0 | V33: 0 | W33: 0 | X33: 0 | Y33: 0 | Z33: 0 | AA33: =U33*$AE$13+V33*$AE$14 -> 0 | AB33: =AA33+S33+N33 -> 0
B34: 3 | C34: 0 | D34: 0 | E34: 0 | F34: 0 | G34: 0 | H34: 0 | I34: 0 | J34: 0 | K34: 0 | L34: 0 | M34: 0 | N34: =G34*$AE$5+H34*$AE$6+I34*$AE$7+J34*$AE$8+K34 -> 0 | O34: 0 | P34: 0 | Q34: 0 | R34: 0 | S34: =IF(O34=0,0,10) -> 0 | T34: 0 | U34: 0 | V34: 0 | W34: 0 | X34: 0 | Y34: 0 | Z34: 0 | AA34: =U34*$AE$13+V34*$AE$14 -> 0 | AB34: =AA34+S34+N34 -> 0
B35: 3 | C35: 0 | D35: 0 | E35: 0 | F35: 0 | G35: 0 | H35: 0 | I35: 0 | J35: 0 | K35: 0 | L35: 0 | M35: 0 | N35: =G35*$AE$5+H35*$AE$6+I35*$AE$7+J35*$AE$8+K35 -> 0 | O35: 0 | P35: 0 | Q35: 0 | R35: 0 | S35: =IF(O35=0,0,10) -> 0 | T35: 0 | U35: 0 | V35: 0 | W35: 0 | X35: 0 | Y35: 0 | Z35: 0 | AA35: =U35*$AE$13+V35*$AE$14 -> 0 | AB35: =AA35+S35+N35 -> 0
AA37: PI43 | AB37: =SUM(AB31:AB33) -> 0
AA38: AI43 | AB38: =IF(AND(AI!$C$7="T",AB37<$AE$19),0,IF(AND(AI!$C$7="T",AB37>$AE$19),3,IF(AND(AI!$C$7="AS",AB37<$AE$20),0,IF(AND(AI!$C$7="AS",AB37>$AE$20),3,IF(AND(AI!$C$7="AJ",AB37<$AE$19),0,IF(AND(AI!$C$7="AJ",AB37>$AE$19),3,IF(AND(AI!$C$7="JTP",AB37<$AE$21),0,IF(AND(AI!$C$7="JTP",AB37>$AE$21),3,IF(AND(AI!$C$7="AY1",AB37<$AE$22),0,IF(AND(AI!$C$7="AY1",AB37>$AE$22),3,IF(AND(AI!$C$7="AY2",AB37=0),0,IF(AND(AI!$C$7="AY2",AB37>1),3,1)))))))))))) -> 0
B42: Año | C42: Revistas científicas | O42: Revista de divulgación científca | T42: Libros
C43: Título del artículo | D43: Autores | E43: Nombre de la | G43: Indexadas | L43: No indexadas | O43: Título del | P43: Autores | Q43: Nombre de la | R43: Referencia | T43: Título del | U43: Completo | V43: Capítulo | X43: Autores | Y43: Indexado | Z43: No indexado
E44: Revista | F44: Referencia | G44: Q1 | H44: Q2 | I44: Q3 | J44: Q4 | K44: IH | L44: Referato | M44: Sin Referato | N44: Prci | O44: Artículo | Q44: Revista | S44: Prdi | T44: Libro | W44: Título | Y44: Referencia | AA44: Pli | AB44: pbi
B45: 4 | C45: Ppooso | D45: Pepe- Juan | E45: Rev Fac Cienc Agrarias | F45: Vol 2 | G45: 0 | H45: 1 | I45: 0 | J45: 0 | K45: 14 | L45: 1 | M45: 0 | N45: =G45*$AE$5+H45*$AE$6+I45*$AE$7+J45*$AE$8+K45 -> 34 | O45: 0 | P45: 0 | Q45: 0 | R45: 0 | S45: =IF(O45=0,0,10) -> 0 | T45: 0 | U45: 0 | V45: 0 | W45: 0 | X45: 0 | Y45: 0 | Z45: 0 | AA45: =U45*$AE$13+V45*$AE$14 -> 0 | AB45: =AA45+S45+N45 -> 34
...

Sheet AI5
B2: AI5 : Participación en reuniones científicas, de divulgación científicas o libros, registros y patentes
B3: Año | C3: Evento | F3: Tipo | K3: Carácter | M3: Participación | X3: Cuadro 3.4.5.1: Vonderación según tipo de evento | AA3: Cuadro 3.4.5.4: Mínimos de PI5 según categoría docente
C4: Nombre | D4: Lugar | E4: Momento | F4: Congreso | G4: Jornada | H4: Worksop | I4: Simposio | J4: Coloquio | L4: Evi | M4: Conferencista | N4: Resumen | O4: Póster | P4: Trabajo Completo | Q4: Expositor | R4: Asistencia | S4: Organización | T4: Evaluador | U4: Epi | V4: pari | X4: Tipo | Y4: Valoración | AA4: Categoría | AB4: Mínimo
B5: 1 | C5: SISI | D5: Mendoza | E5: Marzo | F5: 1 | G5: 0 | H5: 0 | I5: 0 | J5: 0 | K5: UN | L5: =IF(F5=1,$Y$5,IF(G5=1,$Y$6,IF(H5,$Y$7,IF(I5=1,$Y$8,IF(J5=1,$Y$9,0)))))+IF(K5="UN",$Y$13,IF(K5="PR",$Y$14,IF(K5="NAC",$Y$15,IF(K5="INT",$Y$16,IF(K5="NACINT",$Y$17,0))))) -> 40 | M5: 1 | N5: 1 | O5: 1 | P5: 1 | Q5: 1 | R5: 1 | S5: 0 | T5: 0 | U5: =IF(M5=1,$Y$21,0)+IF(N5=1,$Y$22,0)+IF(O5=1,$Y$23,0)+IF(P5=1,$Y$24,0)+IF(Q5=1,$Y$25,0)+IF(R5=1,$Y$26,0)+IF(S5=1,$Y27,0)+IF(T5=1,$Y$28,0) -> 95 | V5: =L5+U5 -> 135 | X5: Congreso | Y5: 20 | AA5: T | AB5: 25
B6: 1 | C6: MOD | D6: Salta | E6: Abril | F6: 0 | G6: 0 | H6: 0 | I6: 0 | J6: 1 | K6: NACINT | L6: =IF(F6=1,$Y$5,IF(G6=1,$Y$6,IF(H6,$Y$7,IF(I6=1,$Y$8,IF(J6=1,$Y$9,0)))))+IF(K6="UN",$Y$13,IF(K6="PR",$Y$14,IF(K6="NAC",$Y$15,IF(K6="INT",$Y$16,IF(K6="NACINT",$Y$17,0))))) -> 55 | M6: 0 | N6: 1 | O6: 1 | P6: 0 | Q6: 0 | R6: 0 | S6: 1 | T6: 0 | U6: =IF(M6=1,$Y$21,0)+IF(N6=1,$Y$22,0)+IF(O6=1,$Y$23,0)+IF(P6=1,$Y$24,0)+IF(Q6=1,$Y$25,0)+IF(R6=1,$Y$26,0)+IF(S6=1,$Y28,0)+IF(T6=1,$Y$28,0) -> 50 | V6: =L6+U6 -> 105 | X6: Jornal | Y6: 15 | AA6: AS | AB6: 25
B7: 1 | C7: LL | D7: Paraguay | E7: Mayo | F7: 1 | G7: 0 | H7: 0 | I7: 0 | J7: 0 | K7: INT | L7: =IF(F7=1,$Y$5,IF(G7=1,$Y$6,IF(H7,$Y$7,IF(I7=1,$Y$8,IF(J7=1,$Y$9,0)))))+IF(K7="UN",$Y$13,IF(K7="PR",$Y$14,IF(K7="NAC",$Y$15,IF(K7="INT",$Y$16,IF(K7="NACINT",$Y$17,0))))) -> 50 | M7: 0 | N7: 0 | O7: 0 | P7: 0 | Q7: 0 | R7: 1 | S7: 0 | T7: 1 | U7: =IF(M7=1,$Y$21,0)+IF(N7=1,$Y$22,0)+IF(O7=1,$Y$23,0)+IF(P7=1,$Y$24,0)+IF(Q7=1,$Y$25,0)+IF(R7=1,$Y$26,0)+IF(S7=1,$Y29,0)+IF(T7=1,$Y$28,0) -> 35 | V7: =L7+U7 -> 85 | X7: Worshop | Y7: 15 | AA7: AJ | AB7: 10
B8: 1 | C8: DDR | D8: Córdoba | E8: Junio | F8: 0 | G8: 1 | H8: 0 | I8: 0 | J8: 0 | K8: NAC | L8: =IF(F8=1,$Y$5,IF(G8=1,$Y$6,IF(H8,$Y$7,IF(I8=1,$Y$8,IF(J8=1,$Y$9,0)))))+IF(K8="UN",$Y$13,IF(K8="PR",$Y$14,IF(K8="NAC",$Y$15,IF(K8="INT",$Y$16,IF(K8="NACINT",$Y$17,0))))) -> 35 | M8: 0 | N8: 1 | O8: 1 | P8: 0 | Q8: 1 | R8: 1 | S8: 0 | T8: 0 | U8: =IF(M8=1,$Y$21,0)+IF(N8=1,$Y$22,0)+IF(O8=1,$Y$23,0)+IF(P8=1,$Y$24,0)+IF(Q8=1,$Y$25,0)+IF(R8=1,$Y$26,0)+IF(S8=1,$Y30,0)+IF(T8=1,$Y$28,0) -> 35 | V8: =L8+U8 -> 70 | X8: Simposio | Y8: 15 | AA8: JTP | AB8: 25
X9: Coloquio | Y9: 15 | AA9: AY1 | AB9: 5
U10: PI51 | V10: =SUM(V5:V8) -> 395 | AA10: AY2 | AB10: 0
U11: AI51 | V11: =IF(AND(AI!$C$7="T",V10<$AB$5),0,IF(AND(AI!$C$7="T",V10>$AB$5),3,IF(AND(AI!$C$7="AS",V10<$AB$6),0,IF(AND(AI!$C$7="AS",V10>$AB$6),3,IF(AND(AI!$C$7="AJ",V10<$AB$7),0,IF(AND(AI!$C$7="AJ",V10>$AB$7),3,IF(AND(AI!$C$7="JTP",V10<$AB$8),0,IF(AND(AI!$C$7="JTP",V10>$AB$8),3,IF(AND(AI!$C$7="AY1",V10<$AB$9),0,IF(AND(AI!$C$7="AY1",V10>$AB$9),3,IF(AND(AI!$C$7="AY2",V10=0),0,IF(AND(AI!$C$7="AY2",V10>1),3,1)))))))))))) -> 3 | X11: Cuadro 3.4.5.2: Valoración según el carácter del evento
X12: Carácter | Y12: Valoración | AA12: Cuadro 3.4.5.5: Valorización de AI5 según valor de PI5
B13: AI5 : Participación en reuniones científicas, de divulgación científicas o libros, registros y patentes | X13: UN | Y13: 20 | AA13: En relación al PI5 | AB13: AI5
B14: Año | C14: Evento | F14: Tipo | K14: Carácter | M14: Participación | X14: PR | Y14: 10 | AA14: Menor al mínimo | AB14: 0
C15: Nombre | D15: Lugar | E15: Momento | F15: Congreso | G15: Jornada | H15: Worksop | I15: Simposio | J15: Coloquio | L15: Evi | M15: Conferencista | N15: Resumen | O15: Póster | P15: Trabajo Completo | Q15: Expositor | R15: Asistencia | S15: Organización | T15: Evaluador | U15: Epi | V15: pari | X15: NAC | Y15: 20 | AA15: Igual al mínimo | AB15: 1
B16: 2 | C16: SISI | D16: Uruguay | E16: Marzo | F16: 0 | G16: 0 | H16: 0 | I16: 1 | J16: 0 | K16: NACINT | L16: =IF(F16=1,$Y$5,IF(G16=1,$Y$6,IF(H16,$Y$7,IF(I16=1,$Y$8,IF(J16=1,$Y$9,0)))))+IF(K16="UN",$Y$13,IF(K16="PR",$Y$14,IF(K16="NAC",$Y$15,IF(K16="INT",$Y$16,IF(K16="NACINT",$Y$17,0))))) -> 55 | M16: 0 | N16: 1 | O16: 1 | P16: 0 | Q16: 1 | R16: 0 | S16: 0 | T16: 0 | U16: =IF(M16=1,$Y$21,0)+IF(N16=1,$Y$22,0)+IF(O16=1,$Y$23,0)+IF(P16=1,$Y$24,0)+IF(Q16=1,$Y$25,0)+IF(R16=1,$Y$26,0)+IF(S16=1,$Y38,0)+IF(T16=1,$Y$28,0) -> 30 | V16: =L16+U16 -> 85 | X16: INT | Y16: 30 | AA16: Mayor al mínimo | AB16: 3
B17: 2 | C17: MOD | D17: Salta | E17: Febrero | F17: 0 | G17: 0 | H17: 0 | I17: 0 | J17: 1 | K17: NAC | L17: =IF(F17=1,$Y$5,IF(G17=1,$Y$6,IF(H17,$Y$7,IF(I17=1,$Y$8,IF(J17=1,$Y$9,0)))))+IF(K17="UN",$Y$13,IF(K17="PR",$Y$14,IF(K17="NAC",$Y$15,IF(K17="INT",$Y$16,IF(K17="NACINT",$Y$17,0))))) -> 35 | M17: 0 | N17: 1 | O17: 1 | P17: 0 | Q17: 0 | R17: 0 | S17: 1 | T17: 0 | U17: =IF(M17=1,$Y$21,0)+IF(N17=1,$Y$22,0)+IF(O17=1,$Y$23,0)+IF(P17=1,$Y$24,0)+IF(Q17=1,$Y$25,0)+IF(R17=1,$Y$26,0)+IF(S17=1,$Y39,0)+IF(T17=1,$Y$28,0) -> 20 | V17: =L17+U17 -> 55 | X17: NACINT | Y17: 40
B18: 2 | F18: 0 | G18: 0 | H18: 0 | I18: 0 | J18: 0 | L18: =IF(F18=1,$Y$5,IF(G18=1,$Y$6,IF(H18,$Y$7,IF(I18=1,$Y$8,IF(J18=1,$Y$9,0)))))+IF(K18="UN",$Y$13,IF(K18="PR",$Y$14,IF(K18="NAC",$Y$15,IF(K18="INT",$Y$16,IF(K18="NACINT",$Y$17,0))))) -> 0 | M18: 0 | N18: 0 | O18: 0 | P18: 0 | Q18: 0 | R18: 0 | S18: 0 | T18: 0 | U18: =IF(M18=1,$Y$21,0)+IF(N18=1,$Y$22,0)+IF(O18=1,$Y$23,0)+IF(P18=1,$Y$24,0)+IF(Q18=1,$Y$25,0)+IF(R18=1,$Y$26,0)+IF(S18=1,$Y40,0)+IF(T18=1,$Y$28,0) -> 0 | V18: =L18+U18 -> 0
B19: 2 | F19: 0 | G19: 0 | H19: 0 | I19: 0 | J19: 0 | L19: =IF(F19=1,$Y$5,IF(G19=1,$Y$6,IF(H19,$Y$7,IF(I19=1,$Y$8,IF(J19=1,$Y$9,0)))))+IF(K19="UN",$Y$13,IF(K19="PR",$Y$14,IF(K19="NAC",$Y$15,IF(K19="INT",$Y$16,IF(K19="NACINT",$Y$17,0))))) -> 0 | M19: 0 | N19: 0 | O19: 0 | P19: 0 | Q19: 0 | R19: 0 | S19: 0 | T19: 0 | U19: =IF(M19=1,$Y$21,0)+IF(N19=1,$Y$22,0)+IF(O19=1,$Y$23,0)+IF(P19=1,$Y$24,0)+IF(Q19=1,$Y$25,0)+IF(R19=1,$Y$26,0)+IF(S19=1,$Y41,0)+IF(T19=1,$Y$28,0) -> 0 | V19: =L19+U19 -> 0 | X19: Cuadro 3.4.5.3: Valoració según la participación en el evento
X20: Carácter | Y20: Valoración
U21: PI52 | V21: =SUM(V16:V19) -> 140 | X21: Conferencista | Y21: 30
U22: AI52 | V22: =IF(AND(AI!$C$8="T",V21<$AB$5),0,IF(AND(AI!$C$8="T",V21>$AB$5),3,IF(AND(AI!$C$8="AS",V21<$AB$6),0,IF(AND(AI!$C$8="AS",V21>$AB$6),3,IF(AND(AI!$C$8="AJ",V21<$AB$7),0,IF(AND(AI!$C$8="AJ",V21>$AB$7),3,IF(AND(AI!$C$8="JTP",V21<$AB$8),0,IF(AND(AI!$C$8="JTP",V21>$AB$8),3,IF(AND(AI!$C$8="AY1",V21<$AB$9),0,IF(AND(AI!$C$8="AY1",V21>$AB$9),3,IF(AND(AI!$C$8="AY2",V21=0),0,IF(AND(AI!$C$8="AY2",V21>1),3,1)))))))))))) -> 3 | X22: Resumen | Y22: 10
X23: Póster | Y23: 10
X24: Trabajo Final | Y24: 30
B25: AI5 : Participación en reuniones científicas, de divulgación científicas o libros, registros y patentes | X25: Expositor | Y25: 10
B26: Año | C26: Evento | F26: Tipo | K26: Carácter | M26: Participación | X26: Asistencia | Y26: 5
C27: Nombre | D27: Lugar | E27: Momento | F27: Congreso | G27: Jornada | H27: Worksop | I27: Simposio | J27: Coloquio | L27: Evi | M27: Conferencista | N27: Resumen | O27: Póster | P27: Trabajo Completo | Q27: Expositor | R27: Asistencia | S27: Organización | T27: Evaluador | U27: Epi | V27: pari | X27: Organización | Y27: 30
B28: 3 | C28: SSIT | D28: San Juan | E28: Octubre | F28: 0 | G28: 0 | H28: 1 | I28: 0 | J28: 0 | K28: NAC | L28: =IF(F28=1,$Y$5,IF(G28=1,$Y$6,IF(H28,$Y$7,IF(I28=1,$Y$8,IF(J28=1,$Y$9,0)))))+IF(K28="UN",$Y$13,IF(K28="PR",$Y$14,IF(K28="NAC",$Y$15,IF(K28="INT",$Y$16,IF(K28="NACINT",$Y$17,0))))) -> 35 | M28: 0 | N28: 1 | O28: 1 | P28: 0 | Q28: 0 | R28: 1 | S28: 0 | T28: 0 | U28: =IF(M28=1,$Y$21,0)+IF(N28=1,$Y$22,0)+IF(O28=1,$Y$23,0)+IF(P28=1,$Y$24,0)+IF(Q28=1,$Y$25,0)+IF(R28=1,$Y$26,0)+IF(S28=1,$Y50,0)+IF(T28=1,$Y$28,0) -> 25 | V28: =L28+U28 -> 60 | X28: Evaluador | Y28: 30
B29: 3 | F29: 0 | G29: 0 | H29: 0 | I29: 0 | J29: 0 | L29: =IF(F29=1,$Y$5,IF(G29=1,$Y$6,IF(H29,$Y$7,IF(I29=1,$Y$8,IF(J29=1,$Y$9,0)))))+IF(K29="UN",$Y$13,IF(K29="PR",$Y$14,IF(K29="NAC",$Y$15,IF(K29="INT",$Y$16,IF(K29="NACINT",$Y$17,0))))) -> 0 | M29: 0 | N29: 0 | O29: 0 | P29: 0 | Q29: 0 | R29: 0 | S29: 0 | T29: 0 | U29: =IF(M29=1,$Y$21,0)+IF(N29=1,$Y$22,0)+IF(O29=1,$Y$23,0)+IF(P29=1,$Y$24,0)+IF(Q29=1,$Y$25,0)+IF(R29=1,$Y$26,0)+IF(S29=1,$Y51,0)+IF(T29=1,$Y$28,0) -> 0 | V29: =L29+U29 -> 0
B30: 3 | F30: 0 | G30: 0 | H30: 0 | I30: 0 | J30: 0 | L30: =IF(F30=1,$Y$5,IF(G30=1,$Y$6,IF(H30,$Y$7,IF(I30=1,$Y$8,IF(J30=1,$Y$9,0)))))+IF(K30="UN",$Y$13,IF(K30="PR",$Y$14,IF(K30="NAC",$Y$15,IF(K30="INT",$Y$16,IF(K30="NACINT",$Y$17,0))))) -> 0 | M30: 0 | N30: 0 | O30: 0 | P30: 0 | Q30: 0 | R30: 0 | S30: 0 | T30: 0 | U30: =IF(M30=1,$Y$21,0)+IF(N30=1,$Y$22,0)+IF(O30=1,$Y$23,0)+IF(P30=1,$Y$24,0)+IF(Q30=1,$Y$25,0)+IF(R30=1,$Y$26,0)+IF(S30=1,$Y52,0)+IF(T30=1,$Y$28,0) -> 0 | V30: =L30+U30 -> 0
B31: 3 | F31: 0 | G31: 0 | H31: 0 | I31: 0 | J31: 0 | L31: =IF(F31=1,$Y$5,IF(G31=1,$Y$6,IF(H31,$Y$7,IF(I31=1,$Y$8,IF(J31=1,$Y$9,0)))))+IF(K31="UN",$Y$13,IF(K31="PR",$Y$14,IF(K31="NAC",$Y$15,IF(K31="INT",$Y$16,IF(K31="NACINT",$Y$17,0))))) -> 0 | M31: 0 | N31: 0 | O31: 0 | P31: 0 | Q31: 0 | R31: 0 | S31: 0 | T31: 0 | U31: =IF(M31=1,$Y$21,0)+IF(N31=1,$Y$22,0)+IF(O31=1,$Y$23,0)+IF(P31=1,$Y$24,0)+IF(Q31=1,$Y$25,0)+IF(R31=1,$Y$26,0)+IF(S31=1,$Y53,0)+IF(T31=1,$Y$28,0) -> 0 | V31: =L31+U31 -> 0
U33: PI53 | V33: =SUM(V28:V31) -> 60
U34: AI53 | V34: =IF(AND(AI!$C$9="T",V33<$AB$5),0,IF(AND(AI!$C$9="T",V33>$AB$5),3,IF(AND(AI!$C$9="AS",V33<$AB$6),0,IF(AND(AI!$C$9="AS",V33>$AB$6),3,IF(AND(AI!$C$9="AJ",V33<$AB$7),0,IF(AND(AI!$C$9="AJ",V33>$AB$7),3,IF(AND(AI!$C$9="JTP",V33<$AB$8),0,IF(AND(AI!$C$9="JTP",V33>$AB$8),3,IF(AND(AI!$C$9="AY1",V33<$AB$9),0,IF(AND(AI!$C$9="AY1",V33>$AB$9),3,IF(AND(AI!$C$9="AY2",V33=0),0,IF(AND(AI!$C$9="AY2",V33>1),3,1)))))))))))) -> 3
B36: AI5 : Participación en reuniones científicas, de divulgación científicas o libros, registros y patentes
B37: Año | C37: Evento | F37: Tipo | K37: Carácter | M37: Participación
C38: Nombre | D38: Lugar | E38: Momento | F38: Congreso | G38: Jornada | H38: Worksop | I38: Simposio | J38: Coloquio | L38: Evi | M38: Conferencista | N38: Resumen | O38: Póster | P38: Trabajo Completo | Q38: Expositor | R38: Asistencia | S38: Organización | T38: Evaluador | U38: Epi | V38: pari
B39: 4 | F39: 0 | G39: 0 | H39: 0 | I39: 0 | J39: 0 | L39: =IF(F39=1,$Y$5,IF(G39=1,$Y$6,IF(H39,$Y$7,IF(I39=1,$Y$8,IF(J39=1,$Y$9,0)))))+IF(K39="UN",$Y$13,IF(K39="PR",$Y$14,IF(K39="NAC",$Y$15,IF(K39="INT",$Y$16,IF(K39="NACINT",$Y$17,0))))) -> 0 | M39: 0 | N39: 0 | O39: 0 | P39: 0 | Q39: 0 | R39: 0 | S39: 0 | T39: 0 | U39: =IF(M39=1,$Y$21,0)+IF(N39=1,$Y$22,0)+IF(O39=1,$Y$23,0)+IF(P39=1,$Y$24,0)+IF(Q39=1,$Y$25,0)+IF(R39=1,$Y$26,0)+IF(S39=1,$Y61,0)+IF(T39=1,$Y$28,0) -> 0 | V39: =L39+U39 -> 0
B40: 4 | F40: 0 | G40: 0 | H40: 0 | I40: 0 | J40: 0 | L40: =IF(F40=1,$Y$5,IF(G40=1,$Y$6,IF(H40,$Y$7,IF(I40=1,$Y$8,IF(J40=1,$Y$9,0)))))+IF(K40="UN",$Y$13,IF(K40="PR",$Y$14,IF(K40="NAC",$Y$15,IF(K40="INT",$Y$16,IF(K40="NACINT",$Y$17,0))))) -> 0 | M40: 0 | N40: 0 | O40: 0 | P40: 0 | Q40: 0 | R40: 0 | S40: 0 | T40: 0 | U40: =IF(M40=1,$Y$21,0)+IF(N40=1,$Y$22,0)+IF(O40=1,$Y$23,0)+IF(P40=1,$Y$24,0)+IF(Q40=1,$Y$25,0)+IF(R40=1,$Y$26,0)+IF(S40=1,$Y62,0)+IF(T40=1,$Y$28,0) -> 0 | V40: =L40+U40 -> 0
B41: 4 | F41: 0 | G41: 0 | H41: 0 | I41: 0 | J41: 0 | L41: =IF(F41=1,$Y$5,IF(G41=1,$Y$6,IF(H41,$Y$7,IF(I41=1,$Y$8,IF(J41=1,$Y$9,0)))))+IF(K41="UN",$Y$13,IF(K41="PR",$Y$14,IF(K41="NAC",$Y$15,IF(K41="INT",$Y$16,IF(K41="NACINT",$Y$17,0))))) -> 0 | M41: 0 | N41: 0 | O41: 0 | P41: 0 | Q41: 0 | R41: 0 | S41: 0 | T41: 0 | U41: =IF(M41=1,$Y$21,0)+IF(N41=1,$Y$22,0)+IF(O41=1,$Y$23,0)+IF(P41=1,$Y$24,0)+IF(Q41=1,$Y$25,0)+IF(R41=1,$Y$26,0)+IF(S41=1,$Y63,0)+IF(T41=1,$Y$28,0) -> 0 | V41: =L41+U41 -> 0
B42: 4 | F42: 0 | G42: 0 | H42: 0 | I42: 0 | J42: 0 | L42: =IF(F42=1,$Y$5,IF(G42=1,$Y$6,IF(H42,$Y$7,IF(I42=1,$Y$8,IF(J42=1,$Y$9,0)))))+IF(K42="UN",$Y$13,IF(K42="PR",$Y$14,IF(K42="NAC",$Y$15,IF(K42="INT",$Y$16,IF(K42="NACINT",$Y$17,0))))) -> 0 | M42: 0 | N42: 0 | O42: 0 | P42: 0 | Q42: 0 | R42: 0 | S42: 0 | T42: 0 | U42: =IF(M42=1,$Y$21,0)+IF(N42=1,$Y$22,0)+IF(O42=1,$Y$23,0)+IF(P42=1,$Y$24,0)+IF(Q42=1,$Y$25,0)+IF(R42=1,$Y$26,0)+IF(S42=1,$Y64,0)+IF(T42=1,$Y$28,0) -> 0 | V42: =L42+U42 -> 0
U44: PI54 | V44: =SUM(V39:V42) -> 0
...

Sheet AI6
B2: AI6 : Miembro de comité editorial y de comisiones evaluadoras | S2: Cuadro3.3.6.1: Valoración según comité rol
B3: Año | C3: Revista | F3: Rol | I3: Tipo de Evaluación | M3: Alcance | S3: Rol | T3: Valoración
C4: Nombre | D4: Indexada | E4: rvip | F4: Comité Editorial | G4: Evaluador | H4: rip | I4: Resúmen | J4: Trabajo Final | K4: Proyectos | L4: tvip | M4: UNCuyo | N4: Provincial | O4: Nac-Inter | P4: aip | Q4: evip | S4: Comité | T4: 10
B5: 1 | C5: Nome | D5: 0 | E5: =IF(AND(C5="",D5=0),0,IF(D5=1,50,20)) -> 20 | F5: 1 | G5: 0 | H5: =IF(F5=1,$T$4,0)+IF(G5=1,$T$5,0) -> 10 | I5: 1 | J5: 0 | K5: 0 | L5: =IF(I5=1,$T$10,0)+IF(J5=1,$T$11,0)+IF(K5=1,$T$12,0) -> 5 | M5: 1 | N5: 0 | O5: 0 | P5: =IF(M5=1,$T$17,IF(N5=1,$T$18,IF(O5=1,$T$19,0))) -> 20 | Q5: =E5+H5+L5+P5 -> 55 | S5: Evaluador | T5: 20
B6: 1 | C6: Coke | D6: 1 | E6: =IF(AND(C6="",D6=0),0,IF(D6=1,50,20)) -> 50 | F6: 0 | G6: 1 | H6: =IF(F6=1,$T$4,0)+IF(G6=1,$T$5,0) -> 20 | I6: 0 | J6: 0 | K6: 0 | L6: =IF(I6=1,$T$10,0)+IF(J6=1,$T$11,0)+IF(K6=1,$T$12,0) -> 0 | M6: 0 | N6: 0 | O6: 0 | P6: =IF(M6=1,$T$17,IF(N6=1,$T$18,IF(O6=1,$T$19,0))) -> 0 | Q6: =E6+H6+L6+P6 -> 70
B7: 1 | D7: 0 | E7: =IF(AND(C7="",D7=0),0,IF(D7=1,50,20)) -> 0 | F7: 0 | G7: 0 | H7: =IF(F7=1,$T$4,0)+IF(G7=1,$T$5,0) -> 0 | I7: 0 | J7: 0 | K7: 0 | L7: =IF(I7=1,$T$10,0)+IF(J7=1,$T$11,0)+IF(K7=1,$T$12,0) -> 0 | M7: 0 | N7: 0 | O7: 0 | P7: =IF(M7=1,$T$17,IF(N7=1,$T$18,IF(O7=1,$T$19,0))) -> 0 | Q7: =E7+H7+L7+P7 -> 0
B8: 1 | D8: 0 | E8: =IF(AND(C8="",D8=0),0,IF(D8=1,50,20)) -> 0 | F8: 0 | G8: 0 | H8: =IF(F8=1,$T$4,0)+IF(G8=1,$T$5,0) -> 0 | I8: 0 | J8: 0 | K8: 0 | L8: =IF(I8=1,$T$10,0)+IF(J8=1,$T$11,0)+IF(K8=1,$T$12,0) -> 0 | M8: 0 | N8: 0 | O8: 0 | P8: =IF(M8=1,$T$17,IF(N8=1,$T$18,IF(O8=1,$T$19,0))) -> 0 | Q8: =E8+H8+L8+P8 -> 0 | S8: Cuadro 3.3.6.2: Valorización según tipo de evaluación
B9: 1 | D9: 0 | E9: =IF(AND(C9="",D9=0),0,IF(D9=1,50,20)) -> 0 | F9: 0 | G9: 0 | H9: =IF(F9=1,$T$4,0)+IF(G9=1,$T$5,0) -> 0 | I9: 0 | J9: 0 | K9: 0 | L9: =IF(I9=1,$T$10,0)+IF(J9=1,$T$11,0)+IF(K9=1,$T$12,0) -> 0 | M9: 0 | N9: 0 | O9: 0 | P9: =IF(M9=1,$T$17,IF(N9=1,$T$18,IF(O9=1,$T$19,0))) -> 0 | Q9: =E9+H9+L9+P9 -> 0 | S9: Tipo | T9: Valoración
B10: 1 | D10: 0 | E10: =IF(AND(C10="",D10=0),0,IF(D10=1,50,20)) -> 0 | F10: 0 | G10: 0 | H10: =IF(F10=1,$T$4,0)+IF(G10=1,$T$5,0) -> 0 | I10: 0 | J10: 0 | K10: 0 | L10: =IF(I10=1,$T$10,0)+IF(J10=1,$T$11,0)+IF(K10=1,$T$12,0) -> 0 | M10: 0 | N10: 0 | O10: 0 | P10: =IF(M10=1,$T$17,IF(N10=1,$T$18,IF(O10=1,$T$19,0))) -> 0 | Q10: =E10+H10+L10+P10 -> 0 | S10: Resumen | T10: 5
S11: Trabajo Final | T11: 15
P12: PI61 | Q12: =SUM(Q5:Q10) -> 125 | S12: Proyectos | T12: 5
P13: AI61 | Q13: =IF(Q12<1,0,IF(Q12<50,1,3)) -> 3
B15: AI6 : Miembro de comité editorial y de comisiones evaluadoras | S15: Cuadro 3.3.6.3: Valoración según alcance de evaluación
B16: Año | C16: Revista | F16: Rol | I16: Tipo de Evaluación | M16: Alcance | S16: Alcance | T16: Valoración
C17: Nombre | D17: Indexada | E17: rvip | F17: Comité Editorial | G17: Evaluador | H17: rip | I17: Resúmen | J17: Trabajo Final | K17: Proyectos | L17: tvip | M17: UNCuyo | N17: Provincial | O17: Nac-Inter | P17: aip | Q17: evip | S17: UNCuyo | T17: 20
B18: 2 | C18: NN | D18: 1 | E18: =IF(AND(C18="",D18=0),0,IF(D18=1,50,20)) -> 50 | F18: 1 | G18: 0 | H18: =IF(F18=1,$T$4,0)+IF(G18=1,$T$5,0) -> 10 | I18: 0 | J18: 1 | K18: 0 | L18: =IF(I18=1,$T$10,0)+IF(J18=1,$T$11,0)+IF(K18=1,$T$12,0) -> 15 | M18: 1 | N18: 0 | O18: 0 | P18: =IF(M18=1,$T$17,IF(N18=1,$T$18,IF(O18=1,$T$19,0))) -> 20 | Q18: =E18+H18+L18+P18 -> 95 | S18: Provincial | T18: 30
B19: 2 | D19: 0 | E19: =IF(AND(C19="",D19=0),0,IF(D19=1,50,20)) -> 0 | F19: 0 | G19: 1 | H19: =IF(F19=1,$T$4,0)+IF(G19=1,$T$5,0) -> 20 | I19: 0 | J19: 0 | K19: 0 | L19: =IF(I19=1,$T$10,0)+IF(J19=1,$T$11,0)+IF(K19=1,$T$12,0) -> 0 | M19: 0 | N19: 0 | O19: 0 | P19: =IF(M19=1,$T$17,IF(N19=1,$T$18,IF(O19=1,$T$19,0))) -> 0 | Q19: =E19+H19+L19+P19 -> 20 | S19: Nacional Internacional | T19: 50
B20: 2 | D20: 0 | E20: =IF(AND(C20="",D20=0),0,IF(D20=1,50,20)) -> 0 | F20: 0 | G20: 0 | H20: =IF(F20=1,$T$4,0)+IF(G20=1,$T$5,0) -> 0 | I20: 0 | J20: 0 | K20: 0 | L20: =IF(I20=1,$T$10,0)+IF(J20=1,$T$11,0)+IF(K20=1,$T$12,0) -> 0 | M20: 0 | N20: 0 | O20: 0 | P20: =IF(M20=1,$T$17,IF(N20=1,$T$18,IF(O20=1,$T$19,0))) -> 0 | Q20: =E20+H20+L20+P20 -> 0
B21: 2 | D21: 0 | E21: =IF(AND(C21="",D21=0),0,IF(D21=1,50,20)) -> 0 | F21: 0 | G21: 0 | H21: =IF(F21=1,$T$4,0)+IF(G21=1,$T$5,0) -> 0 | I21: 0 | J21: 0 | K21: 0 | L21: =IF(I21=1,$T$10,0)+IF(J21=1,$T$11,0)+IF(K21=1,$T$12,0) -> 0 | M21: 0 | N21: 0 | O21: 0 | P21: =IF(M21=1,$T$17,IF(N21=1,$T$18,IF(O21=1,$T$19,0))) -> 0 | Q21: =E21+H21+L21+P21 -> 0
B22: 2 | D22: 0 | E22: =IF(AND(C22="",D22=0),0,IF(D22=1,50,20)) -> 0 | F22: 0 | G22: 0 | H22: =IF(F22=1,$T$4,0)+IF(G22=1,$T$5,0) -> 0 | I22: 0 | J22: 0 | K22: 0 | L22: =IF(I22=1,$T$10,0)+IF(J22=1,$T$11,0)+IF(K22=1,$T$12,0) -> 0 | M22: 0 | N22: 0 | O22: 0 | P22: =IF(M22=1,$T$17,IF(N22=1,$T$18,IF(O22=1,$T$19,0))) -> 0 | Q22: =E22+H22+L22+P22 -> 0 | S22: Cuadro 3.3.6.4: Valorización de AI6 según valor de PI6
B23: 2 | D23: 0 | E23: =IF(AND(C23="",D23=0),0,IF(D23=1,50,20)) -> 0 | F23: 0 | G23: 0 | H23: =IF(F23=1,$T$4,0)+IF(G23=1,$T$5,0) -> 0 | I23: 0 | J23: 0 | K23: 0 | L23: =IF(I23=1,$T$10,0)+IF(J23=1,$T$11,0)+IF(K23=1,$T$12,0) -> 0 | M23: 0 | N23: 0 | O23: 0 | P23: =IF(M23=1,$T$17,IF(N23=1,$T$18,IF(O23=1,$T$19,0))) -> 0 | Q23: =E23+H23+L23+P23 -> 0 | S23: En relación al PI6 | T23: AI6
S24: Igual a 0 | T24: 0
P25: PI62 | Q25: =SUM(Q18:Q23) -> 115 | S25: 1 -50 | T25: 1
P26: AI62 | Q26: =IF(Q25<1,0,IF(Q25<50,1,3)) -> 3 | S26: Mayor a 50 | T26: 3
B29: AI6 : Miembro de comité editorial y de comisiones evaluadoras
B30: Año | C30: Revista | F30: Rol | I30: Tipo de Evaluación | M30: Alcance
C31: Nombre | D31: Indexada | E31: rvip | F31: Comité Editorial | G31: Evaluador | H31: rip | I31: Resúmen | J31: Trabajo Final | K31: Proyectos | L31: tvip | M31: UNCuyo | N31: Provincial | O31: Nac-Inter | P31: aip | Q31: evip
B32: 3 | C32: PP | D32: 1 | E32: =IF(AND(C32="",D32=0),0,IF(D32=1,50,20)) -> 50 | F32: 1 | G32: 0 | H32: =IF(F32=1,$T$4,0)+IF(G32=1,$T$5,0) -> 10 | I32: 0 | J32: 0 | K32: 0 | L32: =IF(I32=1,$T$10,0)+IF(J32=1,$T$11,0)+IF(K32=1,$T$12,0) -> 0 | M32: 1 | N32: 0 | O32: 0 | P32: =IF(M32=1,$T$17,IF(N32=1,$T$18,IF(O32=1,$T$19,0))) -> 20 | Q32: =E32+H32+L32+P32 -> 80
B33: 3 | D33: 0 | E33: =IF(AND(C33="",D33=0),0,IF(D33=1,50,20)) -> 0 | F33: 0 | G33: 0 | H33: =IF(F33=1,$T$4,0)+IF(G33=1,$T$5,0) -> 0 | I33: 0 | J33: 0 | K33: 0 | L33: =IF(I33=1,$T$10,0)+IF(J33=1,$T$11,0)+IF(K33=1,$T$12,0) -> 0 | M33: 0 | N33: 0 | O33: 0 | P33: =IF(M33=1,$T$17,IF(N33=1,$T$18,IF(O33=1,$T$19,0))) -> 0 | Q33: =E33+H33+L33+P33 -> 0
B34: 3 | D34: 0 | E34: =IF(AND(C34="",D34=0),0,IF(D34=1,50,20)) -> 0 | F34: 0 | G34: 0 | H34: =IF(F34=1,$T$4,0)+IF(G34=1,$T$5,0) -> 0 | I34: 0 | J34: 0 | K34: 0 | L34: =IF(I34=1,$T$10,0)+IF(J34=1,$T$11,0)+IF(K34=1,$T$12,0) -> 0 | M34: 0 | N34: 0 | O34: 0 | P34: =IF(M34=1,$T$17,IF(N34=1,$T$18,IF(O34=1,$T$19,0))) -> 0 | Q34: =E34+H34+L34+P34 -> 0
B35: 3 | D35: 0 | E35: =IF(AND(C35="",D35=0),0,IF(D35=1,50,20)) -> 0 | F35: 0 | G35: 0 | H35: =IF(F35=1,$T$4,0)+IF(G35=1,$T$5,0) -> 0 | I35: 0 | J35: 0 | K35: 0 | L35: =IF(I35=1,$T$10,0)+IF(J35=1,$T$11,0)+IF(K35=1,$T$12,0) -> 0 | M35: 0 | N35: 0 | O35: 0 | P35: =IF(M35=1,$T$17,IF(N35=1,$T$18,IF(O35=1,$T$19,0))) -> 0 | Q35: =E35+H35+L35+P35 -> 0
B36: 3 | D36: 0 | E36: =IF(AND(C36="",D36=0),0,IF(D36=1,50,20)) -> 0 | F36: 0 | G36: 0 | H36: =IF(F36=1,$T$4,0)+IF(G36=1,$T$5,0) -> 0 | I36: 0 | J36: 0 | K36: 0 | L36: =IF(I36=1,$T$10,0)+IF(J36=1,$T$11,0)+IF(K36=1,$T$12,0) -> 0 | M36: 0 | N36: 0 | O36: 0 | P36: =IF(M36=1,$T$17,IF(N36=1,$T$18,IF(O36=1,$T$19,0))) -> 0 | Q36: =E36+H36+L36+P36 -> 0
B37: 3 | D37: 0 | E37: =IF(AND(C37="",D37=0),0,IF(D37=1,50,20)) -> 0 | F37: 0 | G37: 0 | H37: =IF(F37=1,$T$4,0)+IF(G37=1,$T$5,0) -> 0 | I37: 0 | J37: 0 | K37: 0 | L37: =IF(I37=1,$T$10,0)+IF(J37=1,$T$11,0)+IF(K37=1,$T$12,0) -> 0 | M37: 0 | N37: 0 | O37: 0 | P37: =IF(M37=1,$T$17,IF(N37=1,$T$18,IF(O37=1,$T$19,0))) -> 0 | Q37: =E37+H37+L37+P37 -> 0
P39: PI63 | Q39: =SUM(Q32:Q37) -> 80
P40: AI63 | Q40: =IF(Q39<1,0,IF(Q39<50,1,3)) -> 3
B43: AI6 : Miembro de comité editorial y de comisiones evaluadoras
B44: Año | C44: Revista | F44: Rol | I44: Tipo de Evaluación | M44: Alcance
C45: Nombre | D45: Indexada | E45: rvip | F45: Comité Editorial | G45: Evaluador | H45: rip | I45: Resúmen | J45: Trabajo Final | K45: Proyectos | L45: tvip | M45: UNCuyo | N45: Provincial | O45: Nac-Inter | P45: aip | Q45: evip
B46: 4 | C46: PP | D46: 1 | E46: =IF(AND(C46="",D46=0),0,IF(D46=1,50,20)) -> 50 | F46: 1 | G46: 0 | H46: =IF(F46=1,$T$4,0)+IF(G46=1,$T$5,0) -> 10 | I46: 0 | J46: 1 | K46: 0 | L46: =IF(I46=1,$T$10,0)+IF(J46=1,$T$11,0)+IF(K46=1,$T$12,0) -> 15 | M46: 1 | N46: 0 | O46: 0 | P46: =IF(M46=1,$T$17,IF(N46=1,$T$18,IF(O46=1,$T$19,0))) -> 20 | Q46: =E46+H46+L46+P46 -> 95
B47: 4 | E47: =IF(AND(C47="",D47=0),0,IF(D47=1,50,20)) -> 0 | F47: 0 | G47: 0 | H47: =IF(F47=1,$T$4,0)+IF(G47=1,$T$5,0) -> 0 | I47: 0 | J47: 0 | K47: 0 | L47: =IF(I47=1,$T$10,0)+IF(J47=1,$T$11,0)+IF(K47=1,$T$12,0) -> 0 | M47: 0 | N47: 0 | O47: 0 | P47: =IF(M47=1,$T$17,IF(N47=1,$T$18,IF(O47=1,$T$19,0))) -> 0 | Q47: =E47+H47+L47+P47 -> 0
...

Sheet Puntaje
B2: Tabla 3: | C2: Puntajes totales obtenidos en cada año, para las diferentes dimensiones de la actividad de investigación declarada | K2: Cuadro 3.1: | L2: Umbrales Básicos para las dimensiones en investigación según categoría y dedicación
B3: Año | C3: PI1 | D3: PI2 | E3: PI3 | F3: PI4 | G3: PI5 | H3: PI6 | I3: Puntaje | K3: Categoría (j) | L3: Dedicación (l) | M3: PI1 | N3: PI2 | O3: PI3 | P3: PI4 | Q3: PI5 | R3: PI6 | S3: UBIjl
